nohup: ignoring input
Watching for file changes with StatReloader
[04/Nov/2020 08:59:55] "GET /news/search/?q=a&from=2020-10-15 HTTP/1.1" 200 62941
Not Found: /
[04/Nov/2020 11:50:41] "GET / HTTP/1.1" 404 2139
Not Found: /favicon.ico
[04/Nov/2020 11:50:41] "GET /favicon.ico HTTP/1.1" 404 2190
[04/Nov/2020 11:51:01] "GET /news/search HTTP/1.1" 301 0
[04/Nov/2020 11:51:01] "GET /news/search/ HTTP/1.1" 200 63845
[04/Nov/2020 11:54:07] "GET /news/index0 HTTP/1.1" 200 11366
Not Found: /
[04/Nov/2020 11:54:41] "GET / HTTP/1.1" 404 2139
----------------------------------------
Exception happened during processing of request from ('58.200.129.218', 56651)
Traceback (most recent call last):
  File "/usr/lib/python3.8/socketserver.py", line 650, in process_request_thread
    self.finish_request(request, client_address)
  File "/usr/lib/python3.8/socketserver.py", line 360, in finish_request
    self.RequestHandlerClass(request, client_address, self)
  File "/usr/lib/python3.8/socketserver.py", line 720, in __init__
    self.handle()
  File "/home/ubuntu/.local/lib/python3.8/site-packages/django/core/servers/basehttp.py", line 174, in handle
    self.handle_one_request()
  File "/home/ubuntu/.local/lib/python3.8/site-packages/django/core/servers/basehttp.py", line 182, in handle_one_request
    self.raw_requestline = self.rfile.readline(65537)
  File "/usr/lib/python3.8/socket.py", line 669, in readinto
    return self._sock.recv_into(b)
ConnectionResetError: [Errno 104] Connection reset by peer
----------------------------------------
[04/Nov/2020 12:06:43] "GET /news/index0 HTTP/1.1" 200 11366
[04/Nov/2020 12:09:14] "GET /news/index0 HTTP/1.1" 200 11366
[04/Nov/2020 12:09:48] "GET /news/index0 HTTP/1.1" 200 11366
[04/Nov/2020 12:09:57] "GET /news/wordcloud/0/30 HTTP/1.1" 200 738
[04/Nov/2020 12:09:59] "GET /news/wordcloud/1/30 HTTP/1.1" 200 690
[04/Nov/2020 12:10:01] "GET /news/wordcloud/2/30 HTTP/1.1" 200 677
[04/Nov/2020 12:10:57] "GET /news/index0 HTTP/1.1" 200 11366
[04/Nov/2020 12:10:58] "GET /news/wordcloud/0/30 HTTP/1.1" 200 738
[04/Nov/2020 12:13:20] "GET /news/wordcloud/0/30 HTTP/1.1" 200 738
[04/Nov/2020 12:13:28] "GET /news/wordcloud/2/30 HTTP/1.1" 200 677
[04/Nov/2020 12:13:31] "GET /news/wordcloud/1/30 HTTP/1.1" 200 690
[04/Nov/2020 12:13:32] "GET /news/wordcloud/4/30 HTTP/1.1" 200 665
[04/Nov/2020 12:13:33] "GET /news/wordcloud/3/30 HTTP/1.1" 200 673
[04/Nov/2020 12:14:19] "GET /news/wordcloud/0/30 HTTP/1.1" 200 738
[04/Nov/2020 12:20:30] "GET /news/wordcloud/19/30 HTTP/1.1" 200 681
[04/Nov/2020 12:21:15] "GET /news/wordcloud/0/30 HTTP/1.1" 200 738
[04/Nov/2020 12:21:21] "GET /news/wordcloud/1/30 HTTP/1.1" 200 690
[04/Nov/2020 12:22:57] "GET /news/wordcloud/0/30 HTTP/1.1" 200 738
[04/Nov/2020 12:23:22] "GET /news/wordcloud/0/30 HTTP/1.1" 200 738
[04/Nov/2020 12:23:24] "GET /news/wordcloud/1/30 HTTP/1.1" 200 690
[04/Nov/2020 12:23:48] "GET /news/wordcloud/0/40 HTTP/1.1" 200 956
[04/Nov/2020 12:23:57] "GET /news/wordcloud/1/40 HTTP/1.1" 200 906
[04/Nov/2020 12:24:11] "GET /news/wordcloud/2/40 HTTP/1.1" 200 893
[04/Nov/2020 12:24:12] "GET /news/wordcloud/3/40 HTTP/1.1" 200 879
[04/Nov/2020 12:24:14] "GET /news/wordcloud/4/40 HTTP/1.1" 200 881
[04/Nov/2020 12:24:16] "GET /news/wordcloud/5/40 HTTP/1.1" 200 989
[04/Nov/2020 12:24:18] "GET /news/wordcloud/6/40 HTTP/1.1" 200 943
[04/Nov/2020 12:24:53] "GET /news/wordcloud/7/40 HTTP/1.1" 200 915
[04/Nov/2020 12:25:16] "GET /news/wordcloud/0/40 HTTP/1.1" 200 956
[04/Nov/2020 12:25:36] "GET /news/wordcloud/1/40 HTTP/1.1" 200 906
[04/Nov/2020 12:25:45] "GET /news/wordcloud/0/40 HTTP/1.1" 200 956
[04/Nov/2020 12:25:56] "GET /news/wordcloud/0/40 HTTP/1.1" 200 956
[04/Nov/2020 12:27:08] "GET /news/wordcloud/1/40 HTTP/1.1" 200 906
[04/Nov/2020 12:27:10] "GET /news/wordcloud/2/40 HTTP/1.1" 200 893
[04/Nov/2020 12:27:22] "GET /news/wordcloud/0/40 HTTP/1.1" 200 956
[04/Nov/2020 12:27:25] "GET /news/wordcloud/1/40 HTTP/1.1" 200 906
[04/Nov/2020 12:28:12] "GET /news/wordcloud/0/40 HTTP/1.1" 200 956
[04/Nov/2020 12:28:37] "GET /news/wordcloud/0/40 HTTP/1.1" 200 956
[04/Nov/2020 12:30:02] "GET /news/wordcloud/0/40 HTTP/1.1" 200 956
[04/Nov/2020 12:30:02] "GET /news/wordcloud/0/40 HTTP/1.1" 200 956
[04/Nov/2020 12:30:03] "GET /news/wordcloud/0/40 HTTP/1.1" 200 956
[04/Nov/2020 12:30:17] "GET /news/wordcloud/0/40 HTTP/1.1" 200 956
[04/Nov/2020 12:30:28] "GET /news/wordcloud/0/40 HTTP/1.1" 200 956
[04/Nov/2020 12:31:03] "GET /news/wordcloud/0/40 HTTP/1.1" 200 956
[04/Nov/2020 12:34:11] "GET /news/wordcloud/0/40 HTTP/1.1" 200 956
[04/Nov/2020 12:34:16] "GET /news/wordcloud/1/40 HTTP/1.1" 200 906
[04/Nov/2020 12:34:18] "GET /news/wordcloud/0/40 HTTP/1.1" 200 956
[04/Nov/2020 12:34:19] "GET /news/wordcloud/1/40 HTTP/1.1" 200 906
[04/Nov/2020 12:34:20] "GET /news/wordcloud/2/40 HTTP/1.1" 200 893
[04/Nov/2020 12:34:21] "GET /news/wordcloud/3/40 HTTP/1.1" 200 879
[04/Nov/2020 12:34:24] "GET /news/wordcloud/4/40 HTTP/1.1" 200 881
[04/Nov/2020 12:34:27] "GET /news/wordcloud/5/40 HTTP/1.1" 200 989
[04/Nov/2020 12:37:09] "GET /news/wordcloud/0/40 HTTP/1.1" 200 956
[04/Nov/2020 12:37:37] "GET /news/index0 HTTP/1.1" 200 11366
[04/Nov/2020 13:41:15] "GET /news/index0 HTTP/1.1" 200 11366
[04/Nov/2020 13:45:06] "GET /news/index0 HTTP/1.1" 200 11366
[04/Nov/2020 13:46:52] "GET /news/wordcloud/0/40 HTTP/1.1" 200 956
[04/Nov/2020 13:46:54] "GET /news/wordcloud/1/40 HTTP/1.1" 200 906
[04/Nov/2020 13:46:57] "GET /news/wordcloud/2/40 HTTP/1.1" 200 893
[04/Nov/2020 13:47:03] "GET /news/wordcloud/3/40 HTTP/1.1" 200 879
[04/Nov/2020 15:04:24] "GET /news/wordcloud/4/40 HTTP/1.1" 200 881
[04/Nov/2020 15:04:26] "GET /news/wordcloud/3/40 HTTP/1.1" 200 879
[04/Nov/2020 15:04:27] "GET /news/wordcloud/4/40 HTTP/1.1" 200 881
[04/Nov/2020 15:04:29] "GET /news/wordcloud/3/40 HTTP/1.1" 200 879
[04/Nov/2020 15:04:32] "GET /news/wordcloud/4/40 HTTP/1.1" 200 881
[04/Nov/2020 15:04:36] "GET /news/wordcloud/5/40 HTTP/1.1" 200 989
[04/Nov/2020 15:04:38] "GET /news/wordcloud/6/40 HTTP/1.1" 200 943
[04/Nov/2020 15:05:24] "GET /news/wordcloud/7/40 HTTP/1.1" 200 915
[04/Nov/2020 15:05:58] "GET /news/wordcloud/8/40 HTTP/1.1" 200 876
[04/Nov/2020 15:06:13] "GET /news/wordcloud/9/40 HTTP/1.1" 200 938
[04/Nov/2020 15:06:15] "GET /news/wordcloud/10/40 HTTP/1.1" 200 953
[04/Nov/2020 15:07:02] "GET /news/wordcloud/0/40 HTTP/1.1" 200 956
[04/Nov/2020 15:07:08] "GET /news/wordcloud/1/40 HTTP/1.1" 200 906
[04/Nov/2020 15:07:11] "GET /news/wordcloud/0/40 HTTP/1.1" 200 956
[04/Nov/2020 15:07:38] "GET /news/wordcloud/0/40 HTTP/1.1" 200 956
[04/Nov/2020 15:07:39] "GET /news/wordcloud/1/40 HTTP/1.1" 200 906
[04/Nov/2020 15:07:51] "GET /news/wordcloud/0/40 HTTP/1.1" 200 956
[04/Nov/2020 15:07:52] "GET /news/wordcloud/19/40 HTTP/1.1" 200 893
[04/Nov/2020 15:07:53] "GET /news/wordcloud/0/40 HTTP/1.1" 200 956
[04/Nov/2020 15:07:54] "GET /news/wordcloud/1/40 HTTP/1.1" 200 906
[04/Nov/2020 15:07:55] "GET /news/wordcloud/2/40 HTTP/1.1" 200 893
[04/Nov/2020 15:07:55] "GET /news/wordcloud/3/40 HTTP/1.1" 200 879
[04/Nov/2020 15:07:56] "GET /news/wordcloud/4/40 HTTP/1.1" 200 881
[04/Nov/2020 15:07:56] "GET /news/wordcloud/5/40 HTTP/1.1" 200 989
[04/Nov/2020 15:07:57] "GET /news/wordcloud/6/40 HTTP/1.1" 200 943
[04/Nov/2020 15:07:57] "GET /news/wordcloud/7/40 HTTP/1.1" 200 915
[04/Nov/2020 15:07:57] "GET /news/wordcloud/8/40 HTTP/1.1" 200 876
[04/Nov/2020 15:08:18] "GET /news/wordcloud/0/40 HTTP/1.1" 200 956
[04/Nov/2020 15:08:20] "GET /news/wordcloud/1/40 HTTP/1.1" 200 906
[04/Nov/2020 15:08:22] "GET /news/wordcloud/2/40 HTTP/1.1" 200 893
[04/Nov/2020 15:08:24] "GET /news/wordcloud/3/40 HTTP/1.1" 200 879
[04/Nov/2020 15:08:25] "GET /news/wordcloud/4/40 HTTP/1.1" 200 881
[04/Nov/2020 15:08:26] "GET /news/wordcloud/5/40 HTTP/1.1" 200 989
[04/Nov/2020 15:08:27] "GET /news/wordcloud/6/40 HTTP/1.1" 200 943
[04/Nov/2020 15:08:28] "GET /news/wordcloud/5/40 HTTP/1.1" 200 989
[04/Nov/2020 15:08:29] "GET /news/wordcloud/4/40 HTTP/1.1" 200 881
[04/Nov/2020 15:08:30] "GET /news/wordcloud/3/40 HTTP/1.1" 200 879
[04/Nov/2020 15:08:31] "GET /news/wordcloud/2/40 HTTP/1.1" 200 893
[04/Nov/2020 15:08:32] "GET /news/wordcloud/1/40 HTTP/1.1" 200 906
[04/Nov/2020 15:08:33] "GET /news/wordcloud/0/40 HTTP/1.1" 200 956
[04/Nov/2020 15:08:34] "GET /news/wordcloud/19/40 HTTP/1.1" 200 893
[04/Nov/2020 15:08:34] "GET /news/wordcloud/18/40 HTTP/1.1" 200 917
[04/Nov/2020 15:08:35] "GET /news/wordcloud/17/40 HTTP/1.1" 200 939
[04/Nov/2020 15:08:59] "GET /news/wordcloud/0/40 HTTP/1.1" 200 956
[04/Nov/2020 15:09:01] "GET /news/wordcloud/1/40 HTTP/1.1" 200 906
[04/Nov/2020 15:09:02] "GET /news/wordcloud/2/40 HTTP/1.1" 200 893
[04/Nov/2020 15:09:05] "GET /news/wordcloud/3/40 HTTP/1.1" 200 879
[04/Nov/2020 15:09:05] "GET /news/wordcloud/4/40 HTTP/1.1" 200 881
[04/Nov/2020 15:09:21] "GET /news/wordcloud/0/40 HTTP/1.1" 200 956
[04/Nov/2020 15:10:09] "GET /news/wordcloud/0/40 HTTP/1.1" 200 956
[04/Nov/2020 15:10:11] "GET /news/wordcloud/1/40 HTTP/1.1" 200 906
[04/Nov/2020 15:10:12] "GET /news/wordcloud/2/40 HTTP/1.1" 200 893
[04/Nov/2020 15:10:13] "GET /news/wordcloud/3/40 HTTP/1.1" 200 879
[04/Nov/2020 15:10:14] "GET /news/wordcloud/2/40 HTTP/1.1" 200 893
[04/Nov/2020 15:10:15] "GET /news/wordcloud/3/40 HTTP/1.1" 200 879
[04/Nov/2020 15:10:16] "GET /news/wordcloud/4/40 HTTP/1.1" 200 881
[04/Nov/2020 15:10:17] "GET /news/wordcloud/3/40 HTTP/1.1" 200 879
[04/Nov/2020 15:11:03] "GET /news/wordcloud/0/40 HTTP/1.1" 200 956
[04/Nov/2020 15:11:05] "GET /news/wordcloud/1/40 HTTP/1.1" 200 906
[04/Nov/2020 15:11:30] "GET /news/wordcloud/0/40 HTTP/1.1" 200 956
[04/Nov/2020 15:11:31] "GET /news/wordcloud/1/40 HTTP/1.1" 200 906
[04/Nov/2020 15:11:33] "GET /news/wordcloud/2/40 HTTP/1.1" 200 893
[04/Nov/2020 15:11:34] "GET /news/wordcloud/3/40 HTTP/1.1" 200 879
[04/Nov/2020 15:11:35] "GET /news/wordcloud/4/40 HTTP/1.1" 200 881
[04/Nov/2020 15:11:57] "GET /news/wordcloud/0/40 HTTP/1.1" 200 956
[04/Nov/2020 15:11:58] "GET /news/wordcloud/1/40 HTTP/1.1" 200 906
[04/Nov/2020 15:12:00] "GET /news/wordcloud/2/40 HTTP/1.1" 200 893
[04/Nov/2020 15:12:31] "GET /news/wordcloud/0/40 HTTP/1.1" 200 956
[04/Nov/2020 15:12:33] "GET /news/wordcloud/1/40 HTTP/1.1" 200 906
[04/Nov/2020 15:13:35] "GET /news/wordcloud/0/40 HTTP/1.1" 200 956
[04/Nov/2020 15:13:36] "GET /news/wordcloud/1/40 HTTP/1.1" 200 906
[04/Nov/2020 15:14:30] "GET /news/wordcloud/2/40 HTTP/1.1" 200 893
[04/Nov/2020 15:14:35] "GET /news/wordcloud/0/40 HTTP/1.1" 200 956
[04/Nov/2020 15:14:36] "GET /news/wordcloud/1/40 HTTP/1.1" 200 906
[04/Nov/2020 15:14:38] "GET /news/wordcloud/2/40 HTTP/1.1" 200 893
[04/Nov/2020 15:14:39] "GET /news/wordcloud/1/40 HTTP/1.1" 200 906
[04/Nov/2020 15:14:40] "GET /news/wordcloud/2/40 HTTP/1.1" 200 893
[04/Nov/2020 15:15:00] "GET /news/wordcloud/0/40 HTTP/1.1" 200 956
[04/Nov/2020 15:15:00] "GET /news/wordcloud/1/40 HTTP/1.1" 200 906
[04/Nov/2020 15:16:39] "GET /news/wordcloud/0/40 HTTP/1.1" 200 956
[04/Nov/2020 15:16:41] "GET /news/wordcloud/1/40 HTTP/1.1" 200 906
[04/Nov/2020 15:16:42] "GET /news/wordcloud/2/40 HTTP/1.1" 200 893
[04/Nov/2020 15:19:04] "GET /news/wordcloud/3/40 HTTP/1.1" 200 879
[04/Nov/2020 15:19:44] "GET /news/wordcloud/0/40 HTTP/1.1" 200 956
[04/Nov/2020 15:19:46] "GET /news/wordcloud/1/40 HTTP/1.1" 200 906
[04/Nov/2020 15:20:06] "GET /news/wordcloud/0/40 HTTP/1.1" 200 956
[04/Nov/2020 15:20:07] "GET /news/wordcloud/1/40 HTTP/1.1" 200 906
[04/Nov/2020 15:20:09] "GET /news/wordcloud/2/40 HTTP/1.1" 200 893
[04/Nov/2020 15:21:08] "GET /news/wordcloud/0/40 HTTP/1.1" 200 956
[04/Nov/2020 15:21:09] "GET /news/wordcloud/1/40 HTTP/1.1" 200 906
[04/Nov/2020 15:21:10] "GET /news/wordcloud/2/40 HTTP/1.1" 200 893
[04/Nov/2020 15:21:33] "GET /news/wordcloud/3/40 HTTP/1.1" 200 879
[04/Nov/2020 15:21:39] "GET /news/wordcloud/0/40 HTTP/1.1" 200 956
[04/Nov/2020 15:27:32] "GET /news/wordcloud/0/40 HTTP/1.1" 200 956
[04/Nov/2020 15:27:34] "GET /news/wordcloud/1/40 HTTP/1.1" 200 906
[04/Nov/2020 15:27:40] "GET /news/wordcloud/2/40 HTTP/1.1" 200 893
[04/Nov/2020 15:28:09] "GET /news/wordcloud/0/40 HTTP/1.1" 200 956
[04/Nov/2020 15:28:27] "GET /news/wordcloud/0/40 HTTP/1.1" 200 956
[04/Nov/2020 15:35:14] "GET /news/wordcloud/0/40 HTTP/1.1" 200 956
[04/Nov/2020 15:36:46] "GET /news/wordcloud/0/40 HTTP/1.1" 200 956
[04/Nov/2020 15:37:36] "GET /news/wordcloud/0/40 HTTP/1.1" 200 956
[04/Nov/2020 15:38:24] "GET /news/wordcloud/0/40 HTTP/1.1" 200 956
[04/Nov/2020 15:39:03] "GET /news/wordcloud/0/40 HTTP/1.1" 200 956
[04/Nov/2020 15:40:33] "GET /news/wordcloud/19/40 HTTP/1.1" 200 893
[04/Nov/2020 15:40:36] "GET /news/wordcloud/18/40 HTTP/1.1" 200 917
[04/Nov/2020 15:40:38] "GET /news/wordcloud/17/40 HTTP/1.1" 200 939
[04/Nov/2020 15:40:50] "GET /news/wordcloud/0/40 HTTP/1.1" 200 956
/home/ubuntu/backend/xxswl-backend/heatmap/dataGenerator.py changed, reloading.
Performing system checks...

System check identified no issues (0 silenced).
November 04, 2020 - 08:58:55
Django version 3.1.1, using settings 'xxswl.settings'
Starting development server at http://0.0.0.0:30000/
Quit the server with CONTROL-C.
a 2020-10-15 None
2
a None None
4
Watching for file changes with StatReloader
[04/Nov/2020 16:30:08] "GET /heatmap/heatmap/9/1602521018.79235845/1602521018.79235845 HTTP/1.1" 200 25
[04/Nov/2020 16:31:15] "GET /news/index0 HTTP/1.1" 200 11366
[04/Nov/2020 16:31:42] "GET /heatmap/heatmap/1/1602521018.79235845/1602521018.79235845 HTTP/1.1" 200 25
/home/ubuntu/backend/xxswl-backend/news/views.py changed, reloading.
Performing system checks...

System check identified no issues (0 silenced).
November 04, 2020 - 15:59:22
Django version 3.1.1, using settings 'xxswl.settings'
Starting development server at http://0.0.0.0:30000/
Quit the server with CONTROL-C.
9 2020-10-12 2020-10-12
1 2020-10-12 2020-10-12
Watching for file changes with StatReloader
Bad Request: /heatmap/heatmap/1/2020-10-16/2020-10-1
[04/Nov/2020 17:01:16] "GET /heatmap/heatmap/1/2020-10-16/2020-10-1 HTTP/1.1" 400 72
[04/Nov/2020 17:01:59] "GET /heatmap/heatmap/9/1602521018.79235845/1602521018.79235845 HTTP/1.1" 200 25
/home/ubuntu/backend/xxswl-backend/heatmap/dataGenerator.py changed, reloading.
Performing system checks...

System check identified no issues (0 silenced).
November 04, 2020 - 16:56:51
Django version 3.1.1, using settings 'xxswl.settings'
Starting development server at http://0.0.0.0:30000/
Quit the server with CONTROL-C.
could not convert string to float: '2020-10-16'
9 2020-10-12 2020-10-12
Watching for file changes with StatReloader
Exception in thread django-main-thread:
Traceback (most recent call last):
  File "/usr/lib/python3.8/threading.py", line 932, in _bootstrap_inner
    self.run()
  File "/usr/lib/python3.8/threading.py", line 870, in run
    self._target(*self._args, **self._kwargs)
  File "/home/ubuntu/.local/lib/python3.8/site-packages/django/utils/autoreload.py", line 53, in wrapper
    fn(*args, **kwargs)
  File "/home/ubuntu/.local/lib/python3.8/site-packages/django/core/management/commands/runserver.py", line 118, in inner_run
    self.check(display_num_errors=True)
  File "/home/ubuntu/.local/lib/python3.8/site-packages/django/core/management/base.py", line 392, in check
    all_issues = checks.run_checks(
  File "/home/ubuntu/.local/lib/python3.8/site-packages/django/core/checks/registry.py", line 70, in run_checks
    new_errors = check(app_configs=app_configs, databases=databases)
  File "/home/ubuntu/.local/lib/python3.8/site-packages/django/core/checks/urls.py", line 13, in check_url_config
    return check_resolver(resolver)
  File "/home/ubuntu/.local/lib/python3.8/site-packages/django/core/checks/urls.py", line 23, in check_resolver
    return check_method()
  File "/home/ubuntu/.local/lib/python3.8/site-packages/django/urls/resolvers.py", line 408, in check
    for pattern in self.url_patterns:
  File "/home/ubuntu/.local/lib/python3.8/site-packages/django/utils/functional.py", line 48, in __get__
    res = instance.__dict__[self.name] = self.func(instance)
  File "/home/ubuntu/.local/lib/python3.8/site-packages/django/urls/resolvers.py", line 589, in url_patterns
    patterns = getattr(self.urlconf_module, "urlpatterns", self.urlconf_module)
  File "/home/ubuntu/.local/lib/python3.8/site-packages/django/utils/functional.py", line 48, in __get__
    res = instance.__dict__[self.name] = self.func(instance)
  File "/home/ubuntu/.local/lib/python3.8/site-packages/django/urls/resolvers.py", line 582, in urlconf_module
    return import_module(self.urlconf_name)
  File "/usr/lib/python3.8/importlib/__init__.py", line 127, in import_module
    return _bootstrap._gcd_import(name[level:], package, level)
  File "<frozen importlib._bootstrap>", line 1014, in _gcd_import
  File "<frozen importlib._bootstrap>", line 991, in _find_and_load
  File "<frozen importlib._bootstrap>", line 975, in _find_and_load_unlocked
  File "<frozen importlib._bootstrap>", line 671, in _load_unlocked
  File "<frozen importlib._bootstrap_external>", line 783, in exec_module
  File "<frozen importlib._bootstrap>", line 219, in _call_with_frames_removed
  File "/home/ubuntu/backend/xxswl-backend/xxswl/urls.py", line 21, in <module>
    path('news/',include('news.urls')),
  File "/home/ubuntu/.local/lib/python3.8/site-packages/django/urls/conf.py", line 34, in include
    urlconf_module = import_module(urlconf_module)
  File "/usr/lib/python3.8/importlib/__init__.py", line 127, in import_module
    return _bootstrap._gcd_import(name[level:], package, level)
  File "<frozen importlib._bootstrap>", line 1014, in _gcd_import
  File "<frozen importlib._bootstrap>", line 991, in _find_and_load
  File "<frozen importlib._bootstrap>", line 975, in _find_and_load_unlocked
  File "<frozen importlib._bootstrap>", line 671, in _load_unlocked
  File "<frozen importlib._bootstrap_external>", line 783, in exec_module
  File "<frozen importlib._bootstrap>", line 219, in _call_with_frames_removed
  File "/home/ubuntu/backend/xxswl-backend/news/urls.py", line 2, in <module>
    from . import views
  File "/home/ubuntu/backend/xxswl-backend/news/views.py", line 10, in <module>
    from heatmap.dataGenerator import data_generator_ids
  File "/home/ubuntu/backend/xxswl-backend/heatmap/dataGenerator.py", line 45
    punctuationPattern = r',|\.|/|;|\'|`|\[|\]|<|>|\?|:|"|\{|\}|\~|!|@|#|\$|%|\^|&|\(|\)|-|=|\_|\+|，|。|、|；|【|】|·|！| |…|（|）|‘|’|“|�?
                                                                                                                                   ^
SyntaxError: EOL while scanning string literal
/home/ubuntu/backend/xxswl-backend/heatmap/dataGenerator.py changed, reloading.
Performing system checks...

Watching for file changes with StatReloader
Exception in thread django-main-thread:
Traceback (most recent call last):
  File "/usr/lib/python3.8/threading.py", line 932, in _bootstrap_inner
    self.run()
  File "/usr/lib/python3.8/threading.py", line 870, in run
    self._target(*self._args, **self._kwargs)
  File "/home/ubuntu/.local/lib/python3.8/site-packages/django/utils/autoreload.py", line 53, in wrapper
    fn(*args, **kwargs)
  File "/home/ubuntu/.local/lib/python3.8/site-packages/django/core/management/commands/runserver.py", line 118, in inner_run
    self.check(display_num_errors=True)
  File "/home/ubuntu/.local/lib/python3.8/site-packages/django/core/management/base.py", line 392, in check
    all_issues = checks.run_checks(
  File "/home/ubuntu/.local/lib/python3.8/site-packages/django/core/checks/registry.py", line 70, in run_checks
    new_errors = check(app_configs=app_configs, databases=databases)
  File "/home/ubuntu/.local/lib/python3.8/site-packages/django/core/checks/urls.py", line 13, in check_url_config
    return check_resolver(resolver)
  File "/home/ubuntu/.local/lib/python3.8/site-packages/django/core/checks/urls.py", line 23, in check_resolver
    return check_method()
  File "/home/ubuntu/.local/lib/python3.8/site-packages/django/urls/resolvers.py", line 408, in check
    for pattern in self.url_patterns:
  File "/home/ubuntu/.local/lib/python3.8/site-packages/django/utils/functional.py", line 48, in __get__
    res = instance.__dict__[self.name] = self.func(instance)
  File "/home/ubuntu/.local/lib/python3.8/site-packages/django/urls/resolvers.py", line 589, in url_patterns
    patterns = getattr(self.urlconf_module, "urlpatterns", self.urlconf_module)
  File "/home/ubuntu/.local/lib/python3.8/site-packages/django/utils/functional.py", line 48, in __get__
    res = instance.__dict__[self.name] = self.func(instance)
  File "/home/ubuntu/.local/lib/python3.8/site-packages/django/urls/resolvers.py", line 582, in urlconf_module
    return import_module(self.urlconf_name)
  File "/usr/lib/python3.8/importlib/__init__.py", line 127, in import_module
    return _bootstrap._gcd_import(name[level:], package, level)
  File "<frozen importlib._bootstrap>", line 1014, in _gcd_import
  File "<frozen importlib._bootstrap>", line 991, in _find_and_load
  File "<frozen importlib._bootstrap>", line 975, in _find_and_load_unlocked
  File "<frozen importlib._bootstrap>", line 671, in _load_unlocked
  File "<frozen importlib._bootstrap_external>", line 783, in exec_module
  File "<frozen importlib._bootstrap>", line 219, in _call_with_frames_removed
  File "/home/ubuntu/backend/xxswl-backend/xxswl/urls.py", line 21, in <module>
    path('news/',include('news.urls')),
  File "/home/ubuntu/.local/lib/python3.8/site-packages/django/urls/conf.py", line 34, in include
    urlconf_module = import_module(urlconf_module)
  File "/usr/lib/python3.8/importlib/__init__.py", line 127, in import_module
    return _bootstrap._gcd_import(name[level:], package, level)
  File "<frozen importlib._bootstrap>", line 1014, in _gcd_import
  File "<frozen importlib._bootstrap>", line 991, in _find_and_load
  File "<frozen importlib._bootstrap>", line 975, in _find_and_load_unlocked
  File "<frozen importlib._bootstrap>", line 671, in _load_unlocked
  File "<frozen importlib._bootstrap_external>", line 783, in exec_module
  File "<frozen importlib._bootstrap>", line 219, in _call_with_frames_removed
  File "/home/ubuntu/backend/xxswl-backend/news/urls.py", line 2, in <module>
    from . import views
  File "/home/ubuntu/backend/xxswl-backend/news/views.py", line 10, in <module>
    from heatmap.dataGenerator import data_generator_ids
  File "/home/ubuntu/backend/xxswl-backend/heatmap/dataGenerator.py", line 45
    punctuationPattern = r',|\.|/|;|\'|`|\[|\]|<|>|\?|:|"|\{|\}|\~|!|@|#|\$|%|\^|&|\(|\)|-|=|\_|\+|，|。|、|；|【|】|·|！| |…|（|）|‘|’|“|�?
                                                                                                                                   ^
SyntaxError: EOL while scanning string literal
/home/ubuntu/backend/xxswl-backend/heatmap/dataGenerator.py changed, reloading.
Performing system checks...

Watching for file changes with StatReloader
Exception in thread django-main-thread:
Traceback (most recent call last):
  File "/usr/lib/python3.8/threading.py", line 932, in _bootstrap_inner
    self.run()
  File "/usr/lib/python3.8/threading.py", line 870, in run
    self._target(*self._args, **self._kwargs)
  File "/home/ubuntu/.local/lib/python3.8/site-packages/django/utils/autoreload.py", line 53, in wrapper
    fn(*args, **kwargs)
  File "/home/ubuntu/.local/lib/python3.8/site-packages/django/core/management/commands/runserver.py", line 118, in inner_run
    self.check(display_num_errors=True)
  File "/home/ubuntu/.local/lib/python3.8/site-packages/django/core/management/base.py", line 392, in check
    all_issues = checks.run_checks(
  File "/home/ubuntu/.local/lib/python3.8/site-packages/django/core/checks/registry.py", line 70, in run_checks
    new_errors = check(app_configs=app_configs, databases=databases)
  File "/home/ubuntu/.local/lib/python3.8/site-packages/django/core/checks/urls.py", line 13, in check_url_config
    return check_resolver(resolver)
  File "/home/ubuntu/.local/lib/python3.8/site-packages/django/core/checks/urls.py", line 23, in check_resolver
    return check_method()
  File "/home/ubuntu/.local/lib/python3.8/site-packages/django/urls/resolvers.py", line 408, in check
    for pattern in self.url_patterns:
  File "/home/ubuntu/.local/lib/python3.8/site-packages/django/utils/functional.py", line 48, in __get__
    res = instance.__dict__[self.name] = self.func(instance)
  File "/home/ubuntu/.local/lib/python3.8/site-packages/django/urls/resolvers.py", line 589, in url_patterns
    patterns = getattr(self.urlconf_module, "urlpatterns", self.urlconf_module)
  File "/home/ubuntu/.local/lib/python3.8/site-packages/django/utils/functional.py", line 48, in __get__
    res = instance.__dict__[self.name] = self.func(instance)
  File "/home/ubuntu/.local/lib/python3.8/site-packages/django/urls/resolvers.py", line 582, in urlconf_module
    return import_module(self.urlconf_name)
  File "/usr/lib/python3.8/importlib/__init__.py", line 127, in import_module
    return _bootstrap._gcd_import(name[level:], package, level)
  File "<frozen importlib._bootstrap>", line 1014, in _gcd_import
  File "<frozen importlib._bootstrap>", line 991, in _find_and_load
  File "<frozen importlib._bootstrap>", line 975, in _find_and_load_unlocked
  File "<frozen importlib._bootstrap>", line 671, in _load_unlocked
  File "<frozen importlib._bootstrap_external>", line 783, in exec_module
  File "<frozen importlib._bootstrap>", line 219, in _call_with_frames_removed
  File "/home/ubuntu/backend/xxswl-backend/xxswl/urls.py", line 21, in <module>
    path('news/',include('news.urls')),
  File "/home/ubuntu/.local/lib/python3.8/site-packages/django/urls/conf.py", line 34, in include
    urlconf_module = import_module(urlconf_module)
  File "/usr/lib/python3.8/importlib/__init__.py", line 127, in import_module
    return _bootstrap._gcd_import(name[level:], package, level)
  File "<frozen importlib._bootstrap>", line 1014, in _gcd_import
  File "<frozen importlib._bootstrap>", line 991, in _find_and_load
  File "<frozen importlib._bootstrap>", line 975, in _find_and_load_unlocked
  File "<frozen importlib._bootstrap>", line 671, in _load_unlocked
  File "<frozen importlib._bootstrap_external>", line 783, in exec_module
  File "<frozen importlib._bootstrap>", line 219, in _call_with_frames_removed
  File "/home/ubuntu/backend/xxswl-backend/news/urls.py", line 2, in <module>
    from . import views
  File "/home/ubuntu/backend/xxswl-backend/news/views.py", line 10, in <module>
    from heatmap.dataGenerator import data_generator_ids
  File "/home/ubuntu/backend/xxswl-backend/heatmap/dataGenerator.py", line 22
SyntaxError: (unicode error) 'utf-8' codec can't decode byte 0xa3 in position 72: invalid start byte
/home/ubuntu/backend/xxswl-backend/heatmap/dataGenerator.py changed, reloading.
Performing system checks...

Watching for file changes with StatReloader
Exception in thread django-main-thread:
Traceback (most recent call last):
  File "/usr/lib/python3.8/threading.py", line 932, in _bootstrap_inner
    self.run()
  File "/usr/lib/python3.8/threading.py", line 870, in run
    self._target(*self._args, **self._kwargs)
  File "/home/ubuntu/.local/lib/python3.8/site-packages/django/utils/autoreload.py", line 53, in wrapper
    fn(*args, **kwargs)
  File "/home/ubuntu/.local/lib/python3.8/site-packages/django/core/management/commands/runserver.py", line 118, in inner_run
    self.check(display_num_errors=True)
  File "/home/ubuntu/.local/lib/python3.8/site-packages/django/core/management/base.py", line 392, in check
    all_issues = checks.run_checks(
  File "/home/ubuntu/.local/lib/python3.8/site-packages/django/core/checks/registry.py", line 70, in run_checks
    new_errors = check(app_configs=app_configs, databases=databases)
  File "/home/ubuntu/.local/lib/python3.8/site-packages/django/core/checks/urls.py", line 13, in check_url_config
    return check_resolver(resolver)
  File "/home/ubuntu/.local/lib/python3.8/site-packages/django/core/checks/urls.py", line 23, in check_resolver
    return check_method()
  File "/home/ubuntu/.local/lib/python3.8/site-packages/django/urls/resolvers.py", line 408, in check
    for pattern in self.url_patterns:
  File "/home/ubuntu/.local/lib/python3.8/site-packages/django/utils/functional.py", line 48, in __get__
    res = instance.__dict__[self.name] = self.func(instance)
  File "/home/ubuntu/.local/lib/python3.8/site-packages/django/urls/resolvers.py", line 589, in url_patterns
    patterns = getattr(self.urlconf_module, "urlpatterns", self.urlconf_module)
  File "/home/ubuntu/.local/lib/python3.8/site-packages/django/utils/functional.py", line 48, in __get__
    res = instance.__dict__[self.name] = self.func(instance)
  File "/home/ubuntu/.local/lib/python3.8/site-packages/django/urls/resolvers.py", line 582, in urlconf_module
    return import_module(self.urlconf_name)
  File "/usr/lib/python3.8/importlib/__init__.py", line 127, in import_module
    return _bootstrap._gcd_import(name[level:], package, level)
  File "<frozen importlib._bootstrap>", line 1014, in _gcd_import
  File "<frozen importlib._bootstrap>", line 991, in _find_and_load
  File "<frozen importlib._bootstrap>", line 975, in _find_and_load_unlocked
  File "<frozen importlib._bootstrap>", line 671, in _load_unlocked
  File "<frozen importlib._bootstrap_external>", line 783, in exec_module
  File "<frozen importlib._bootstrap>", line 219, in _call_with_frames_removed
  File "/home/ubuntu/backend/xxswl-backend/xxswl/urls.py", line 21, in <module>
    path('news/',include('news.urls')),
  File "/home/ubuntu/.local/lib/python3.8/site-packages/django/urls/conf.py", line 34, in include
    urlconf_module = import_module(urlconf_module)
  File "/usr/lib/python3.8/importlib/__init__.py", line 127, in import_module
    return _bootstrap._gcd_import(name[level:], package, level)
  File "<frozen importlib._bootstrap>", line 1014, in _gcd_import
  File "<frozen importlib._bootstrap>", line 991, in _find_and_load
  File "<frozen importlib._bootstrap>", line 975, in _find_and_load_unlocked
  File "<frozen importlib._bootstrap>", line 671, in _load_unlocked
  File "<frozen importlib._bootstrap_external>", line 783, in exec_module
  File "<frozen importlib._bootstrap>", line 219, in _call_with_frames_removed
  File "/home/ubuntu/backend/xxswl-backend/news/urls.py", line 2, in <module>
    from . import views
  File "/home/ubuntu/backend/xxswl-backend/news/views.py", line 10, in <module>
    from heatmap.dataGenerator import data_generator_ids
  File "/home/ubuntu/backend/xxswl-backend/heatmap/dataGenerator.py", line 22
SyntaxError: (unicode error) 'utf-8' codec can't decode byte 0xa3 in position 69: invalid start byte
/home/ubuntu/backend/xxswl-backend/heatmap/dataGenerator.py changed, reloading.
Performing system checks...

Watching for file changes with StatReloader
Exception in thread django-main-thread:
Traceback (most recent call last):
  File "/usr/lib/python3.8/threading.py", line 932, in _bootstrap_inner
    self.run()
  File "/usr/lib/python3.8/threading.py", line 870, in run
    self._target(*self._args, **self._kwargs)
  File "/home/ubuntu/.local/lib/python3.8/site-packages/django/utils/autoreload.py", line 53, in wrapper
    fn(*args, **kwargs)
  File "/home/ubuntu/.local/lib/python3.8/site-packages/django/core/management/commands/runserver.py", line 118, in inner_run
    self.check(display_num_errors=True)
  File "/home/ubuntu/.local/lib/python3.8/site-packages/django/core/management/base.py", line 392, in check
    all_issues = checks.run_checks(
  File "/home/ubuntu/.local/lib/python3.8/site-packages/django/core/checks/registry.py", line 70, in run_checks
    new_errors = check(app_configs=app_configs, databases=databases)
  File "/home/ubuntu/.local/lib/python3.8/site-packages/django/core/checks/urls.py", line 13, in check_url_config
    return check_resolver(resolver)
  File "/home/ubuntu/.local/lib/python3.8/site-packages/django/core/checks/urls.py", line 23, in check_resolver
    return check_method()
  File "/home/ubuntu/.local/lib/python3.8/site-packages/django/urls/resolvers.py", line 408, in check
    for pattern in self.url_patterns:
  File "/home/ubuntu/.local/lib/python3.8/site-packages/django/utils/functional.py", line 48, in __get__
    res = instance.__dict__[self.name] = self.func(instance)
  File "/home/ubuntu/.local/lib/python3.8/site-packages/django/urls/resolvers.py", line 589, in url_patterns
    patterns = getattr(self.urlconf_module, "urlpatterns", self.urlconf_module)
  File "/home/ubuntu/.local/lib/python3.8/site-packages/django/utils/functional.py", line 48, in __get__
    res = instance.__dict__[self.name] = self.func(instance)
  File "/home/ubuntu/.local/lib/python3.8/site-packages/django/urls/resolvers.py", line 582, in urlconf_module
    return import_module(self.urlconf_name)
  File "/usr/lib/python3.8/importlib/__init__.py", line 127, in import_module
    return _bootstrap._gcd_import(name[level:], package, level)
  File "<frozen importlib._bootstrap>", line 1014, in _gcd_import
  File "<frozen importlib._bootstrap>", line 991, in _find_and_load
  File "<frozen importlib._bootstrap>", line 975, in _find_and_load_unlocked
  File "<frozen importlib._bootstrap>", line 671, in _load_unlocked
  File "<frozen importlib._bootstrap_external>", line 783, in exec_module
  File "<frozen importlib._bootstrap>", line 219, in _call_with_frames_removed
  File "/home/ubuntu/backend/xxswl-backend/xxswl/urls.py", line 21, in <module>
    path('news/',include('news.urls')),
  File "/home/ubuntu/.local/lib/python3.8/site-packages/django/urls/conf.py", line 34, in include
    urlconf_module = import_module(urlconf_module)
  File "/usr/lib/python3.8/importlib/__init__.py", line 127, in import_module
    return _bootstrap._gcd_import(name[level:], package, level)
  File "<frozen importlib._bootstrap>", line 1014, in _gcd_import
  File "<frozen importlib._bootstrap>", line 991, in _find_and_load
  File "<frozen importlib._bootstrap>", line 975, in _find_and_load_unlocked
  File "<frozen importlib._bootstrap>", line 671, in _load_unlocked
  File "<frozen importlib._bootstrap_external>", line 783, in exec_module
  File "<frozen importlib._bootstrap>", line 219, in _call_with_frames_removed
  File "/home/ubuntu/backend/xxswl-backend/news/urls.py", line 2, in <module>
    from . import views
  File "/home/ubuntu/backend/xxswl-backend/news/views.py", line 10, in <module>
    from heatmap.dataGenerator import data_generator_ids
  File "/home/ubuntu/backend/xxswl-backend/heatmap/dataGenerator.py", line 22
SyntaxError: (unicode error) 'utf-8' codec can't decode byte 0xa3 in position 67: invalid start byte
/home/ubuntu/backend/xxswl-backend/heatmap/dataGenerator.py changed, reloading.
Performing system checks...

Watching for file changes with StatReloader
Exception in thread django-main-thread:
Traceback (most recent call last):
  File "/usr/lib/python3.8/threading.py", line 932, in _bootstrap_inner
    self.run()
  File "/usr/lib/python3.8/threading.py", line 870, in run
    self._target(*self._args, **self._kwargs)
  File "/home/ubuntu/.local/lib/python3.8/site-packages/django/utils/autoreload.py", line 53, in wrapper
    fn(*args, **kwargs)
  File "/home/ubuntu/.local/lib/python3.8/site-packages/django/core/management/commands/runserver.py", line 118, in inner_run
    self.check(display_num_errors=True)
  File "/home/ubuntu/.local/lib/python3.8/site-packages/django/core/management/base.py", line 392, in check
    all_issues = checks.run_checks(
  File "/home/ubuntu/.local/lib/python3.8/site-packages/django/core/checks/registry.py", line 70, in run_checks
    new_errors = check(app_configs=app_configs, databases=databases)
  File "/home/ubuntu/.local/lib/python3.8/site-packages/django/core/checks/urls.py", line 13, in check_url_config
    return check_resolver(resolver)
  File "/home/ubuntu/.local/lib/python3.8/site-packages/django/core/checks/urls.py", line 23, in check_resolver
    return check_method()
  File "/home/ubuntu/.local/lib/python3.8/site-packages/django/urls/resolvers.py", line 408, in check
    for pattern in self.url_patterns:
  File "/home/ubuntu/.local/lib/python3.8/site-packages/django/utils/functional.py", line 48, in __get__
    res = instance.__dict__[self.name] = self.func(instance)
  File "/home/ubuntu/.local/lib/python3.8/site-packages/django/urls/resolvers.py", line 589, in url_patterns
    patterns = getattr(self.urlconf_module, "urlpatterns", self.urlconf_module)
  File "/home/ubuntu/.local/lib/python3.8/site-packages/django/utils/functional.py", line 48, in __get__
    res = instance.__dict__[self.name] = self.func(instance)
  File "/home/ubuntu/.local/lib/python3.8/site-packages/django/urls/resolvers.py", line 582, in urlconf_module
    return import_module(self.urlconf_name)
  File "/usr/lib/python3.8/importlib/__init__.py", line 127, in import_module
    return _bootstrap._gcd_import(name[level:], package, level)
  File "<frozen importlib._bootstrap>", line 1014, in _gcd_import
  File "<frozen importlib._bootstrap>", line 991, in _find_and_load
  File "<frozen importlib._bootstrap>", line 975, in _find_and_load_unlocked
  File "<frozen importlib._bootstrap>", line 671, in _load_unlocked
  File "<frozen importlib._bootstrap_external>", line 783, in exec_module
  File "<frozen importlib._bootstrap>", line 219, in _call_with_frames_removed
  File "/home/ubuntu/backend/xxswl-backend/xxswl/urls.py", line 21, in <module>
    path('news/',include('news.urls')),
  File "/home/ubuntu/.local/lib/python3.8/site-packages/django/urls/conf.py", line 34, in include
    urlconf_module = import_module(urlconf_module)
  File "/usr/lib/python3.8/importlib/__init__.py", line 127, in import_module
    return _bootstrap._gcd_import(name[level:], package, level)
  File "<frozen importlib._bootstrap>", line 1014, in _gcd_import
  File "<frozen importlib._bootstrap>", line 991, in _find_and_load
  File "<frozen importlib._bootstrap>", line 975, in _find_and_load_unlocked
  File "<frozen importlib._bootstrap>", line 671, in _load_unlocked
  File "<frozen importlib._bootstrap_external>", line 783, in exec_module
  File "<frozen importlib._bootstrap>", line 219, in _call_with_frames_removed
  File "/home/ubuntu/backend/xxswl-backend/news/urls.py", line 2, in <module>
    from . import views
  File "/home/ubuntu/backend/xxswl-backend/news/views.py", line 10, in <module>
    from heatmap.dataGenerator import data_generator_ids
  File "/home/ubuntu/backend/xxswl-backend/heatmap/dataGenerator.py", line 22
SyntaxError: (unicode error) 'utf-8' codec can't decode byte 0xa3 in position 72: invalid start byte
/home/ubuntu/backend/xxswl-backend/heatmap/dataGenerator.py changed, reloading.
Performing system checks...

Watching for file changes with StatReloader
Exception in thread django-main-thread:
Traceback (most recent call last):
  File "/usr/lib/python3.8/threading.py", line 932, in _bootstrap_inner
    self.run()
  File "/usr/lib/python3.8/threading.py", line 870, in run
    self._target(*self._args, **self._kwargs)
  File "/home/ubuntu/.local/lib/python3.8/site-packages/django/utils/autoreload.py", line 53, in wrapper
    fn(*args, **kwargs)
  File "/home/ubuntu/.local/lib/python3.8/site-packages/django/core/management/commands/runserver.py", line 118, in inner_run
    self.check(display_num_errors=True)
  File "/home/ubuntu/.local/lib/python3.8/site-packages/django/core/management/base.py", line 392, in check
    all_issues = checks.run_checks(
  File "/home/ubuntu/.local/lib/python3.8/site-packages/django/core/checks/registry.py", line 70, in run_checks
    new_errors = check(app_configs=app_configs, databases=databases)
  File "/home/ubuntu/.local/lib/python3.8/site-packages/django/core/checks/urls.py", line 13, in check_url_config
    return check_resolver(resolver)
  File "/home/ubuntu/.local/lib/python3.8/site-packages/django/core/checks/urls.py", line 23, in check_resolver
    return check_method()
  File "/home/ubuntu/.local/lib/python3.8/site-packages/django/urls/resolvers.py", line 408, in check
    for pattern in self.url_patterns:
  File "/home/ubuntu/.local/lib/python3.8/site-packages/django/utils/functional.py", line 48, in __get__
    res = instance.__dict__[self.name] = self.func(instance)
  File "/home/ubuntu/.local/lib/python3.8/site-packages/django/urls/resolvers.py", line 589, in url_patterns
    patterns = getattr(self.urlconf_module, "urlpatterns", self.urlconf_module)
  File "/home/ubuntu/.local/lib/python3.8/site-packages/django/utils/functional.py", line 48, in __get__
    res = instance.__dict__[self.name] = self.func(instance)
  File "/home/ubuntu/.local/lib/python3.8/site-packages/django/urls/resolvers.py", line 582, in urlconf_module
    return import_module(self.urlconf_name)
  File "/usr/lib/python3.8/importlib/__init__.py", line 127, in import_module
    return _bootstrap._gcd_import(name[level:], package, level)
  File "<frozen importlib._bootstrap>", line 1014, in _gcd_import
  File "<frozen importlib._bootstrap>", line 991, in _find_and_load
  File "<frozen importlib._bootstrap>", line 975, in _find_and_load_unlocked
  File "<frozen importlib._bootstrap>", line 671, in _load_unlocked
  File "<frozen importlib._bootstrap_external>", line 783, in exec_module
  File "<frozen importlib._bootstrap>", line 219, in _call_with_frames_removed
  File "/home/ubuntu/backend/xxswl-backend/xxswl/urls.py", line 21, in <module>
    path('news/',include('news.urls')),
  File "/home/ubuntu/.local/lib/python3.8/site-packages/django/urls/conf.py", line 34, in include
    urlconf_module = import_module(urlconf_module)
  File "/usr/lib/python3.8/importlib/__init__.py", line 127, in import_module
    return _bootstrap._gcd_import(name[level:], package, level)
  File "<frozen importlib._bootstrap>", line 1014, in _gcd_import
  File "<frozen importlib._bootstrap>", line 991, in _find_and_load
  File "<frozen importlib._bootstrap>", line 975, in _find_and_load_unlocked
  File "<frozen importlib._bootstrap>", line 671, in _load_unlocked
  File "<frozen importlib._bootstrap_external>", line 783, in exec_module
  File "<frozen importlib._bootstrap>", line 219, in _call_with_frames_removed
  File "/home/ubuntu/backend/xxswl-backend/news/urls.py", line 2, in <module>
    from . import views
  File "/home/ubuntu/backend/xxswl-backend/news/views.py", line 10, in <module>
    from heatmap.dataGenerator import data_generator_ids
  File "/home/ubuntu/backend/xxswl-backend/heatmap/dataGenerator.py", line 22
SyntaxError: (unicode error) 'utf-8' codec can't decode byte 0xa3 in position 72: invalid start byte
/home/ubuntu/backend/xxswl-backend/heatmap/dataGenerator.py changed, reloading.
Performing system checks...

Watching for file changes with StatReloader
Exception in thread django-main-thread:
Traceback (most recent call last):
  File "/usr/lib/python3.8/threading.py", line 932, in _bootstrap_inner
    self.run()
  File "/usr/lib/python3.8/threading.py", line 870, in run
    self._target(*self._args, **self._kwargs)
  File "/home/ubuntu/.local/lib/python3.8/site-packages/django/utils/autoreload.py", line 53, in wrapper
    fn(*args, **kwargs)
  File "/home/ubuntu/.local/lib/python3.8/site-packages/django/core/management/commands/runserver.py", line 118, in inner_run
    self.check(display_num_errors=True)
  File "/home/ubuntu/.local/lib/python3.8/site-packages/django/core/management/base.py", line 392, in check
    all_issues = checks.run_checks(
  File "/home/ubuntu/.local/lib/python3.8/site-packages/django/core/checks/registry.py", line 70, in run_checks
    new_errors = check(app_configs=app_configs, databases=databases)
  File "/home/ubuntu/.local/lib/python3.8/site-packages/django/core/checks/urls.py", line 13, in check_url_config
    return check_resolver(resolver)
  File "/home/ubuntu/.local/lib/python3.8/site-packages/django/core/checks/urls.py", line 23, in check_resolver
    return check_method()
  File "/home/ubuntu/.local/lib/python3.8/site-packages/django/urls/resolvers.py", line 408, in check
    for pattern in self.url_patterns:
  File "/home/ubuntu/.local/lib/python3.8/site-packages/django/utils/functional.py", line 48, in __get__
    res = instance.__dict__[self.name] = self.func(instance)
  File "/home/ubuntu/.local/lib/python3.8/site-packages/django/urls/resolvers.py", line 589, in url_patterns
    patterns = getattr(self.urlconf_module, "urlpatterns", self.urlconf_module)
  File "/home/ubuntu/.local/lib/python3.8/site-packages/django/utils/functional.py", line 48, in __get__
    res = instance.__dict__[self.name] = self.func(instance)
  File "/home/ubuntu/.local/lib/python3.8/site-packages/django/urls/resolvers.py", line 582, in urlconf_module
    return import_module(self.urlconf_name)
  File "/usr/lib/python3.8/importlib/__init__.py", line 127, in import_module
    return _bootstrap._gcd_import(name[level:], package, level)
  File "<frozen importlib._bootstrap>", line 1014, in _gcd_import
  File "<frozen importlib._bootstrap>", line 991, in _find_and_load
  File "<frozen importlib._bootstrap>", line 975, in _find_and_load_unlocked
  File "<frozen importlib._bootstrap>", line 671, in _load_unlocked
  File "<frozen importlib._bootstrap_external>", line 783, in exec_module
  File "<frozen importlib._bootstrap>", line 219, in _call_with_frames_removed
  File "/home/ubuntu/backend/xxswl-backend/xxswl/urls.py", line 21, in <module>
    path('news/',include('news.urls')),
  File "/home/ubuntu/.local/lib/python3.8/site-packages/django/urls/conf.py", line 34, in include
    urlconf_module = import_module(urlconf_module)
  File "/usr/lib/python3.8/importlib/__init__.py", line 127, in import_module
    return _bootstrap._gcd_import(name[level:], package, level)
  File "<frozen importlib._bootstrap>", line 1014, in _gcd_import
  File "<frozen importlib._bootstrap>", line 991, in _find_and_load
  File "<frozen importlib._bootstrap>", line 975, in _find_and_load_unlocked
  File "<frozen importlib._bootstrap>", line 671, in _load_unlocked
  File "<frozen importlib._bootstrap_external>", line 783, in exec_module
  File "<frozen importlib._bootstrap>", line 219, in _call_with_frames_removed
  File "/home/ubuntu/backend/xxswl-backend/news/urls.py", line 2, in <module>
    from . import views
  File "/home/ubuntu/backend/xxswl-backend/news/views.py", line 10, in <module>
    from heatmap.dataGenerator import data_generator_ids
  File "/home/ubuntu/backend/xxswl-backend/heatmap/dataGenerator.py", line 22
SyntaxError: (unicode error) 'utf-8' codec can't decode byte 0xa3 in position 70: invalid start byte
/home/ubuntu/backend/xxswl-backend/heatmap/dataGenerator.py changed, reloading.
Performing system checks...

Watching for file changes with StatReloader
Exception in thread django-main-thread:
Traceback (most recent call last):
  File "/usr/lib/python3.8/threading.py", line 932, in _bootstrap_inner
    self.run()
  File "/usr/lib/python3.8/threading.py", line 870, in run
    self._target(*self._args, **self._kwargs)
  File "/home/ubuntu/.local/lib/python3.8/site-packages/django/utils/autoreload.py", line 53, in wrapper
    fn(*args, **kwargs)
  File "/home/ubuntu/.local/lib/python3.8/site-packages/django/core/management/commands/runserver.py", line 118, in inner_run
    self.check(display_num_errors=True)
  File "/home/ubuntu/.local/lib/python3.8/site-packages/django/core/management/base.py", line 392, in check
    all_issues = checks.run_checks(
  File "/home/ubuntu/.local/lib/python3.8/site-packages/django/core/checks/registry.py", line 70, in run_checks
    new_errors = check(app_configs=app_configs, databases=databases)
  File "/home/ubuntu/.local/lib/python3.8/site-packages/django/core/checks/urls.py", line 13, in check_url_config
    return check_resolver(resolver)
  File "/home/ubuntu/.local/lib/python3.8/site-packages/django/core/checks/urls.py", line 23, in check_resolver
    return check_method()
  File "/home/ubuntu/.local/lib/python3.8/site-packages/django/urls/resolvers.py", line 408, in check
    for pattern in self.url_patterns:
  File "/home/ubuntu/.local/lib/python3.8/site-packages/django/utils/functional.py", line 48, in __get__
    res = instance.__dict__[self.name] = self.func(instance)
  File "/home/ubuntu/.local/lib/python3.8/site-packages/django/urls/resolvers.py", line 589, in url_patterns
    patterns = getattr(self.urlconf_module, "urlpatterns", self.urlconf_module)
  File "/home/ubuntu/.local/lib/python3.8/site-packages/django/utils/functional.py", line 48, in __get__
    res = instance.__dict__[self.name] = self.func(instance)
  File "/home/ubuntu/.local/lib/python3.8/site-packages/django/urls/resolvers.py", line 582, in urlconf_module
    return import_module(self.urlconf_name)
  File "/usr/lib/python3.8/importlib/__init__.py", line 127, in import_module
    return _bootstrap._gcd_import(name[level:], package, level)
  File "<frozen importlib._bootstrap>", line 1014, in _gcd_import
  File "<frozen importlib._bootstrap>", line 991, in _find_and_load
  File "<frozen importlib._bootstrap>", line 975, in _find_and_load_unlocked
  File "<frozen importlib._bootstrap>", line 671, in _load_unlocked
  File "<frozen importlib._bootstrap_external>", line 783, in exec_module
  File "<frozen importlib._bootstrap>", line 219, in _call_with_frames_removed
  File "/home/ubuntu/backend/xxswl-backend/xxswl/urls.py", line 21, in <module>
    path('news/',include('news.urls')),
  File "/home/ubuntu/.local/lib/python3.8/site-packages/django/urls/conf.py", line 34, in include
    urlconf_module = import_module(urlconf_module)
  File "/usr/lib/python3.8/importlib/__init__.py", line 127, in import_module
    return _bootstrap._gcd_import(name[level:], package, level)
  File "<frozen importlib._bootstrap>", line 1014, in _gcd_import
  File "<frozen importlib._bootstrap>", line 991, in _find_and_load
  File "<frozen importlib._bootstrap>", line 975, in _find_and_load_unlocked
  File "<frozen importlib._bootstrap>", line 671, in _load_unlocked
  File "<frozen importlib._bootstrap_external>", line 783, in exec_module
  File "<frozen importlib._bootstrap>", line 219, in _call_with_frames_removed
  File "/home/ubuntu/backend/xxswl-backend/news/urls.py", line 2, in <module>
    from . import views
  File "/home/ubuntu/backend/xxswl-backend/news/views.py", line 10, in <module>
    from heatmap.dataGenerator import data_generator_ids
  File "/home/ubuntu/backend/xxswl-backend/heatmap/dataGenerator.py", line 22
SyntaxError: (unicode error) 'utf-8' codec can't decode byte 0xa3 in position 68: invalid start byte
/home/ubuntu/backend/xxswl-backend/heatmap/dataGenerator.py changed, reloading.
Performing system checks...

Watching for file changes with StatReloader
Exception in thread django-main-thread:
Traceback (most recent call last):
  File "/usr/lib/python3.8/threading.py", line 932, in _bootstrap_inner
    self.run()
  File "/usr/lib/python3.8/threading.py", line 870, in run
    self._target(*self._args, **self._kwargs)
  File "/home/ubuntu/.local/lib/python3.8/site-packages/django/utils/autoreload.py", line 53, in wrapper
    fn(*args, **kwargs)
  File "/home/ubuntu/.local/lib/python3.8/site-packages/django/core/management/commands/runserver.py", line 118, in inner_run
    self.check(display_num_errors=True)
  File "/home/ubuntu/.local/lib/python3.8/site-packages/django/core/management/base.py", line 392, in check
    all_issues = checks.run_checks(
  File "/home/ubuntu/.local/lib/python3.8/site-packages/django/core/checks/registry.py", line 70, in run_checks
    new_errors = check(app_configs=app_configs, databases=databases)
  File "/home/ubuntu/.local/lib/python3.8/site-packages/django/core/checks/urls.py", line 13, in check_url_config
    return check_resolver(resolver)
  File "/home/ubuntu/.local/lib/python3.8/site-packages/django/core/checks/urls.py", line 23, in check_resolver
    return check_method()
  File "/home/ubuntu/.local/lib/python3.8/site-packages/django/urls/resolvers.py", line 408, in check
    for pattern in self.url_patterns:
  File "/home/ubuntu/.local/lib/python3.8/site-packages/django/utils/functional.py", line 48, in __get__
    res = instance.__dict__[self.name] = self.func(instance)
  File "/home/ubuntu/.local/lib/python3.8/site-packages/django/urls/resolvers.py", line 589, in url_patterns
    patterns = getattr(self.urlconf_module, "urlpatterns", self.urlconf_module)
  File "/home/ubuntu/.local/lib/python3.8/site-packages/django/utils/functional.py", line 48, in __get__
    res = instance.__dict__[self.name] = self.func(instance)
  File "/home/ubuntu/.local/lib/python3.8/site-packages/django/urls/resolvers.py", line 582, in urlconf_module
    return import_module(self.urlconf_name)
  File "/usr/lib/python3.8/importlib/__init__.py", line 127, in import_module
    return _bootstrap._gcd_import(name[level:], package, level)
  File "<frozen importlib._bootstrap>", line 1014, in _gcd_import
  File "<frozen importlib._bootstrap>", line 991, in _find_and_load
  File "<frozen importlib._bootstrap>", line 975, in _find_and_load_unlocked
  File "<frozen importlib._bootstrap>", line 671, in _load_unlocked
  File "<frozen importlib._bootstrap_external>", line 783, in exec_module
  File "<frozen importlib._bootstrap>", line 219, in _call_with_frames_removed
  File "/home/ubuntu/backend/xxswl-backend/xxswl/urls.py", line 21, in <module>
    path('news/',include('news.urls')),
  File "/home/ubuntu/.local/lib/python3.8/site-packages/django/urls/conf.py", line 34, in include
    urlconf_module = import_module(urlconf_module)
  File "/usr/lib/python3.8/importlib/__init__.py", line 127, in import_module
    return _bootstrap._gcd_import(name[level:], package, level)
  File "<frozen importlib._bootstrap>", line 1014, in _gcd_import
  File "<frozen importlib._bootstrap>", line 991, in _find_and_load
  File "<frozen importlib._bootstrap>", line 975, in _find_and_load_unlocked
  File "<frozen importlib._bootstrap>", line 671, in _load_unlocked
  File "<frozen importlib._bootstrap_external>", line 783, in exec_module
  File "<frozen importlib._bootstrap>", line 219, in _call_with_frames_removed
  File "/home/ubuntu/backend/xxswl-backend/news/urls.py", line 2, in <module>
    from . import views
  File "/home/ubuntu/backend/xxswl-backend/news/views.py", line 10, in <module>
    from heatmap.dataGenerator import data_generator_ids
  File "/home/ubuntu/backend/xxswl-backend/heatmap/dataGenerator.py", line 22
SyntaxError: (unicode error) 'utf-8' codec can't decode byte 0xa3 in position 66: invalid start byte
/home/ubuntu/backend/xxswl-backend/heatmap/dataGenerator.py changed, reloading.
Performing system checks...

Watching for file changes with StatReloader
Exception in thread django-main-thread:
Traceback (most recent call last):
  File "/usr/lib/python3.8/threading.py", line 932, in _bootstrap_inner
    self.run()
  File "/usr/lib/python3.8/threading.py", line 870, in run
    self._target(*self._args, **self._kwargs)
  File "/home/ubuntu/.local/lib/python3.8/site-packages/django/utils/autoreload.py", line 53, in wrapper
    fn(*args, **kwargs)
  File "/home/ubuntu/.local/lib/python3.8/site-packages/django/core/management/commands/runserver.py", line 118, in inner_run
    self.check(display_num_errors=True)
  File "/home/ubuntu/.local/lib/python3.8/site-packages/django/core/management/base.py", line 392, in check
    all_issues = checks.run_checks(
  File "/home/ubuntu/.local/lib/python3.8/site-packages/django/core/checks/registry.py", line 70, in run_checks
    new_errors = check(app_configs=app_configs, databases=databases)
  File "/home/ubuntu/.local/lib/python3.8/site-packages/django/core/checks/urls.py", line 13, in check_url_config
    return check_resolver(resolver)
  File "/home/ubuntu/.local/lib/python3.8/site-packages/django/core/checks/urls.py", line 23, in check_resolver
    return check_method()
  File "/home/ubuntu/.local/lib/python3.8/site-packages/django/urls/resolvers.py", line 408, in check
    for pattern in self.url_patterns:
  File "/home/ubuntu/.local/lib/python3.8/site-packages/django/utils/functional.py", line 48, in __get__
    res = instance.__dict__[self.name] = self.func(instance)
  File "/home/ubuntu/.local/lib/python3.8/site-packages/django/urls/resolvers.py", line 589, in url_patterns
    patterns = getattr(self.urlconf_module, "urlpatterns", self.urlconf_module)
  File "/home/ubuntu/.local/lib/python3.8/site-packages/django/utils/functional.py", line 48, in __get__
    res = instance.__dict__[self.name] = self.func(instance)
  File "/home/ubuntu/.local/lib/python3.8/site-packages/django/urls/resolvers.py", line 582, in urlconf_module
    return import_module(self.urlconf_name)
  File "/usr/lib/python3.8/importlib/__init__.py", line 127, in import_module
    return _bootstrap._gcd_import(name[level:], package, level)
  File "<frozen importlib._bootstrap>", line 1014, in _gcd_import
  File "<frozen importlib._bootstrap>", line 991, in _find_and_load
  File "<frozen importlib._bootstrap>", line 975, in _find_and_load_unlocked
  File "<frozen importlib._bootstrap>", line 671, in _load_unlocked
  File "<frozen importlib._bootstrap_external>", line 783, in exec_module
  File "<frozen importlib._bootstrap>", line 219, in _call_with_frames_removed
  File "/home/ubuntu/backend/xxswl-backend/xxswl/urls.py", line 21, in <module>
    path('news/',include('news.urls')),
  File "/home/ubuntu/.local/lib/python3.8/site-packages/django/urls/conf.py", line 34, in include
    urlconf_module = import_module(urlconf_module)
  File "/usr/lib/python3.8/importlib/__init__.py", line 127, in import_module
    return _bootstrap._gcd_import(name[level:], package, level)
  File "<frozen importlib._bootstrap>", line 1014, in _gcd_import
  File "<frozen importlib._bootstrap>", line 991, in _find_and_load
  File "<frozen importlib._bootstrap>", line 975, in _find_and_load_unlocked
  File "<frozen importlib._bootstrap>", line 671, in _load_unlocked
  File "<frozen importlib._bootstrap_external>", line 783, in exec_module
  File "<frozen importlib._bootstrap>", line 219, in _call_with_frames_removed
  File "/home/ubuntu/backend/xxswl-backend/news/urls.py", line 2, in <module>
    from . import views
  File "/home/ubuntu/backend/xxswl-backend/news/views.py", line 10, in <module>
    from heatmap.dataGenerator import data_generator_ids
  File "/home/ubuntu/backend/xxswl-backend/heatmap/dataGenerator.py", line 22
SyntaxError: (unicode error) 'utf-8' codec can't decode byte 0xa3 in position 24: invalid start byte
/home/ubuntu/backend/xxswl-backend/heatmap/dataGenerator.py changed, reloading.
Performing system checks...

Watching for file changes with StatReloader
Exception in thread django-main-thread:
Traceback (most recent call last):
  File "/usr/lib/python3.8/threading.py", line 932, in _bootstrap_inner
    self.run()
  File "/usr/lib/python3.8/threading.py", line 870, in run
    self._target(*self._args, **self._kwargs)
  File "/home/ubuntu/.local/lib/python3.8/site-packages/django/utils/autoreload.py", line 53, in wrapper
    fn(*args, **kwargs)
  File "/home/ubuntu/.local/lib/python3.8/site-packages/django/core/management/commands/runserver.py", line 118, in inner_run
    self.check(display_num_errors=True)
  File "/home/ubuntu/.local/lib/python3.8/site-packages/django/core/management/base.py", line 392, in check
    all_issues = checks.run_checks(
  File "/home/ubuntu/.local/lib/python3.8/site-packages/django/core/checks/registry.py", line 70, in run_checks
    new_errors = check(app_configs=app_configs, databases=databases)
  File "/home/ubuntu/.local/lib/python3.8/site-packages/django/core/checks/urls.py", line 13, in check_url_config
    return check_resolver(resolver)
  File "/home/ubuntu/.local/lib/python3.8/site-packages/django/core/checks/urls.py", line 23, in check_resolver
    return check_method()
  File "/home/ubuntu/.local/lib/python3.8/site-packages/django/urls/resolvers.py", line 408, in check
    for pattern in self.url_patterns:
  File "/home/ubuntu/.local/lib/python3.8/site-packages/django/utils/functional.py", line 48, in __get__
    res = instance.__dict__[self.name] = self.func(instance)
  File "/home/ubuntu/.local/lib/python3.8/site-packages/django/urls/resolvers.py", line 589, in url_patterns
    patterns = getattr(self.urlconf_module, "urlpatterns", self.urlconf_module)
  File "/home/ubuntu/.local/lib/python3.8/site-packages/django/utils/functional.py", line 48, in __get__
    res = instance.__dict__[self.name] = self.func(instance)
  File "/home/ubuntu/.local/lib/python3.8/site-packages/django/urls/resolvers.py", line 582, in urlconf_module
    return import_module(self.urlconf_name)
  File "/usr/lib/python3.8/importlib/__init__.py", line 127, in import_module
    return _bootstrap._gcd_import(name[level:], package, level)
  File "<frozen importlib._bootstrap>", line 1014, in _gcd_import
  File "<frozen importlib._bootstrap>", line 991, in _find_and_load
  File "<frozen importlib._bootstrap>", line 975, in _find_and_load_unlocked
  File "<frozen importlib._bootstrap>", line 671, in _load_unlocked
  File "<frozen importlib._bootstrap_external>", line 783, in exec_module
  File "<frozen importlib._bootstrap>", line 219, in _call_with_frames_removed
  File "/home/ubuntu/backend/xxswl-backend/xxswl/urls.py", line 21, in <module>
    path('news/',include('news.urls')),
  File "/home/ubuntu/.local/lib/python3.8/site-packages/django/urls/conf.py", line 34, in include
    urlconf_module = import_module(urlconf_module)
  File "/usr/lib/python3.8/importlib/__init__.py", line 127, in import_module
    return _bootstrap._gcd_import(name[level:], package, level)
  File "<frozen importlib._bootstrap>", line 1014, in _gcd_import
  File "<frozen importlib._bootstrap>", line 991, in _find_and_load
  File "<frozen importlib._bootstrap>", line 975, in _find_and_load_unlocked
  File "<frozen importlib._bootstrap>", line 671, in _load_unlocked
  File "<frozen importlib._bootstrap_external>", line 783, in exec_module
  File "<frozen importlib._bootstrap>", line 219, in _call_with_frames_removed
  File "/home/ubuntu/backend/xxswl-backend/news/urls.py", line 2, in <module>
    from . import views
  File "/home/ubuntu/backend/xxswl-backend/news/views.py", line 10, in <module>
    from heatmap.dataGenerator import data_generator_ids
  File "/home/ubuntu/backend/xxswl-backend/heatmap/dataGenerator.py", line 22
SyntaxError: (unicode error) 'utf-8' codec can't decode byte 0xa3 in position 24: invalid start byte
/home/ubuntu/backend/xxswl-backend/heatmap/dataGenerator.py changed, reloading.
Performing system checks...

Watching for file changes with StatReloader
Exception in thread django-main-thread:
Traceback (most recent call last):
  File "/usr/lib/python3.8/threading.py", line 932, in _bootstrap_inner
    self.run()
  File "/usr/lib/python3.8/threading.py", line 870, in run
    self._target(*self._args, **self._kwargs)
  File "/home/ubuntu/.local/lib/python3.8/site-packages/django/utils/autoreload.py", line 53, in wrapper
    fn(*args, **kwargs)
  File "/home/ubuntu/.local/lib/python3.8/site-packages/django/core/management/commands/runserver.py", line 118, in inner_run
    self.check(display_num_errors=True)
  File "/home/ubuntu/.local/lib/python3.8/site-packages/django/core/management/base.py", line 392, in check
    all_issues = checks.run_checks(
  File "/home/ubuntu/.local/lib/python3.8/site-packages/django/core/checks/registry.py", line 70, in run_checks
    new_errors = check(app_configs=app_configs, databases=databases)
  File "/home/ubuntu/.local/lib/python3.8/site-packages/django/core/checks/urls.py", line 13, in check_url_config
    return check_resolver(resolver)
  File "/home/ubuntu/.local/lib/python3.8/site-packages/django/core/checks/urls.py", line 23, in check_resolver
    return check_method()
  File "/home/ubuntu/.local/lib/python3.8/site-packages/django/urls/resolvers.py", line 408, in check
    for pattern in self.url_patterns:
  File "/home/ubuntu/.local/lib/python3.8/site-packages/django/utils/functional.py", line 48, in __get__
    res = instance.__dict__[self.name] = self.func(instance)
  File "/home/ubuntu/.local/lib/python3.8/site-packages/django/urls/resolvers.py", line 589, in url_patterns
    patterns = getattr(self.urlconf_module, "urlpatterns", self.urlconf_module)
  File "/home/ubuntu/.local/lib/python3.8/site-packages/django/utils/functional.py", line 48, in __get__
    res = instance.__dict__[self.name] = self.func(instance)
  File "/home/ubuntu/.local/lib/python3.8/site-packages/django/urls/resolvers.py", line 582, in urlconf_module
    return import_module(self.urlconf_name)
  File "/usr/lib/python3.8/importlib/__init__.py", line 127, in import_module
    return _bootstrap._gcd_import(name[level:], package, level)
  File "<frozen importlib._bootstrap>", line 1014, in _gcd_import
  File "<frozen importlib._bootstrap>", line 991, in _find_and_load
  File "<frozen importlib._bootstrap>", line 975, in _find_and_load_unlocked
  File "<frozen importlib._bootstrap>", line 671, in _load_unlocked
  File "<frozen importlib._bootstrap_external>", line 783, in exec_module
  File "<frozen importlib._bootstrap>", line 219, in _call_with_frames_removed
  File "/home/ubuntu/backend/xxswl-backend/xxswl/urls.py", line 21, in <module>
    path('news/',include('news.urls')),
  File "/home/ubuntu/.local/lib/python3.8/site-packages/django/urls/conf.py", line 34, in include
    urlconf_module = import_module(urlconf_module)
  File "/usr/lib/python3.8/importlib/__init__.py", line 127, in import_module
    return _bootstrap._gcd_import(name[level:], package, level)
  File "<frozen importlib._bootstrap>", line 1014, in _gcd_import
  File "<frozen importlib._bootstrap>", line 991, in _find_and_load
  File "<frozen importlib._bootstrap>", line 975, in _find_and_load_unlocked
  File "<frozen importlib._bootstrap>", line 671, in _load_unlocked
  File "<frozen importlib._bootstrap_external>", line 783, in exec_module
  File "<frozen importlib._bootstrap>", line 219, in _call_with_frames_removed
  File "/home/ubuntu/backend/xxswl-backend/news/urls.py", line 2, in <module>
    from . import views
  File "/home/ubuntu/backend/xxswl-backend/news/views.py", line 10, in <module>
    from heatmap.dataGenerator import data_generator_ids
  File "/home/ubuntu/backend/xxswl-backend/heatmap/dataGenerator.py", line 23
SyntaxError: (unicode error) 'utf-8' codec can't decode byte 0xa3 in position 17: invalid start byte
/home/ubuntu/backend/xxswl-backend/heatmap/dataGenerator.py changed, reloading.
Performing system checks...

Watching for file changes with StatReloader
Exception in thread django-main-thread:
Traceback (most recent call last):
  File "/usr/lib/python3.8/threading.py", line 932, in _bootstrap_inner
    self.run()
  File "/usr/lib/python3.8/threading.py", line 870, in run
    self._target(*self._args, **self._kwargs)
  File "/home/ubuntu/.local/lib/python3.8/site-packages/django/utils/autoreload.py", line 53, in wrapper
    fn(*args, **kwargs)
  File "/home/ubuntu/.local/lib/python3.8/site-packages/django/core/management/commands/runserver.py", line 118, in inner_run
    self.check(display_num_errors=True)
  File "/home/ubuntu/.local/lib/python3.8/site-packages/django/core/management/base.py", line 392, in check
    all_issues = checks.run_checks(
  File "/home/ubuntu/.local/lib/python3.8/site-packages/django/core/checks/registry.py", line 70, in run_checks
    new_errors = check(app_configs=app_configs, databases=databases)
  File "/home/ubuntu/.local/lib/python3.8/site-packages/django/core/checks/urls.py", line 13, in check_url_config
    return check_resolver(resolver)
  File "/home/ubuntu/.local/lib/python3.8/site-packages/django/core/checks/urls.py", line 23, in check_resolver
    return check_method()
  File "/home/ubuntu/.local/lib/python3.8/site-packages/django/urls/resolvers.py", line 408, in check
    for pattern in self.url_patterns:
  File "/home/ubuntu/.local/lib/python3.8/site-packages/django/utils/functional.py", line 48, in __get__
    res = instance.__dict__[self.name] = self.func(instance)
  File "/home/ubuntu/.local/lib/python3.8/site-packages/django/urls/resolvers.py", line 589, in url_patterns
    patterns = getattr(self.urlconf_module, "urlpatterns", self.urlconf_module)
  File "/home/ubuntu/.local/lib/python3.8/site-packages/django/utils/functional.py", line 48, in __get__
    res = instance.__dict__[self.name] = self.func(instance)
  File "/home/ubuntu/.local/lib/python3.8/site-packages/django/urls/resolvers.py", line 582, in urlconf_module
    return import_module(self.urlconf_name)
  File "/usr/lib/python3.8/importlib/__init__.py", line 127, in import_module
    return _bootstrap._gcd_import(name[level:], package, level)
  File "<frozen importlib._bootstrap>", line 1014, in _gcd_import
  File "<frozen importlib._bootstrap>", line 991, in _find_and_load
  File "<frozen importlib._bootstrap>", line 975, in _find_and_load_unlocked
  File "<frozen importlib._bootstrap>", line 671, in _load_unlocked
  File "<frozen importlib._bootstrap_external>", line 783, in exec_module
  File "<frozen importlib._bootstrap>", line 219, in _call_with_frames_removed
  File "/home/ubuntu/backend/xxswl-backend/xxswl/urls.py", line 21, in <module>
    path('news/',include('news.urls')),
  File "/home/ubuntu/.local/lib/python3.8/site-packages/django/urls/conf.py", line 34, in include
    urlconf_module = import_module(urlconf_module)
  File "/usr/lib/python3.8/importlib/__init__.py", line 127, in import_module
    return _bootstrap._gcd_import(name[level:], package, level)
  File "<frozen importlib._bootstrap>", line 1014, in _gcd_import
  File "<frozen importlib._bootstrap>", line 991, in _find_and_load
  File "<frozen importlib._bootstrap>", line 975, in _find_and_load_unlocked
  File "<frozen importlib._bootstrap>", line 671, in _load_unlocked
  File "<frozen importlib._bootstrap_external>", line 783, in exec_module
  File "<frozen importlib._bootstrap>", line 219, in _call_with_frames_removed
  File "/home/ubuntu/backend/xxswl-backend/news/urls.py", line 2, in <module>
    from . import views
  File "/home/ubuntu/backend/xxswl-backend/news/views.py", line 10, in <module>
    from heatmap.dataGenerator import data_generator_ids
  File "/home/ubuntu/backend/xxswl-backend/heatmap/dataGenerator.py", line 23
SyntaxError: (unicode error) 'utf-8' codec can't decode byte 0xa3 in position 11: invalid start byte
/home/ubuntu/backend/xxswl-backend/heatmap/dataGenerator.py changed, reloading.
Performing system checks...

Watching for file changes with StatReloader
Exception in thread django-main-thread:
Traceback (most recent call last):
  File "/usr/lib/python3.8/threading.py", line 932, in _bootstrap_inner
    self.run()
  File "/usr/lib/python3.8/threading.py", line 870, in run
    self._target(*self._args, **self._kwargs)
  File "/home/ubuntu/.local/lib/python3.8/site-packages/django/utils/autoreload.py", line 53, in wrapper
    fn(*args, **kwargs)
  File "/home/ubuntu/.local/lib/python3.8/site-packages/django/core/management/commands/runserver.py", line 118, in inner_run
    self.check(display_num_errors=True)
  File "/home/ubuntu/.local/lib/python3.8/site-packages/django/core/management/base.py", line 392, in check
    all_issues = checks.run_checks(
  File "/home/ubuntu/.local/lib/python3.8/site-packages/django/core/checks/registry.py", line 70, in run_checks
    new_errors = check(app_configs=app_configs, databases=databases)
  File "/home/ubuntu/.local/lib/python3.8/site-packages/django/core/checks/urls.py", line 13, in check_url_config
    return check_resolver(resolver)
  File "/home/ubuntu/.local/lib/python3.8/site-packages/django/core/checks/urls.py", line 23, in check_resolver
    return check_method()
  File "/home/ubuntu/.local/lib/python3.8/site-packages/django/urls/resolvers.py", line 408, in check
    for pattern in self.url_patterns:
  File "/home/ubuntu/.local/lib/python3.8/site-packages/django/utils/functional.py", line 48, in __get__
    res = instance.__dict__[self.name] = self.func(instance)
  File "/home/ubuntu/.local/lib/python3.8/site-packages/django/urls/resolvers.py", line 589, in url_patterns
    patterns = getattr(self.urlconf_module, "urlpatterns", self.urlconf_module)
  File "/home/ubuntu/.local/lib/python3.8/site-packages/django/utils/functional.py", line 48, in __get__
    res = instance.__dict__[self.name] = self.func(instance)
  File "/home/ubuntu/.local/lib/python3.8/site-packages/django/urls/resolvers.py", line 582, in urlconf_module
    return import_module(self.urlconf_name)
  File "/usr/lib/python3.8/importlib/__init__.py", line 127, in import_module
    return _bootstrap._gcd_import(name[level:], package, level)
  File "<frozen importlib._bootstrap>", line 1014, in _gcd_import
  File "<frozen importlib._bootstrap>", line 991, in _find_and_load
  File "<frozen importlib._bootstrap>", line 975, in _find_and_load_unlocked
  File "<frozen importlib._bootstrap>", line 671, in _load_unlocked
  File "<frozen importlib._bootstrap_external>", line 783, in exec_module
  File "<frozen importlib._bootstrap>", line 219, in _call_with_frames_removed
  File "/home/ubuntu/backend/xxswl-backend/xxswl/urls.py", line 21, in <module>
    path('news/',include('news.urls')),
  File "/home/ubuntu/.local/lib/python3.8/site-packages/django/urls/conf.py", line 34, in include
    urlconf_module = import_module(urlconf_module)
  File "/usr/lib/python3.8/importlib/__init__.py", line 127, in import_module
    return _bootstrap._gcd_import(name[level:], package, level)
  File "<frozen importlib._bootstrap>", line 1014, in _gcd_import
  File "<frozen importlib._bootstrap>", line 991, in _find_and_load
  File "<frozen importlib._bootstrap>", line 975, in _find_and_load_unlocked
  File "<frozen importlib._bootstrap>", line 671, in _load_unlocked
  File "<frozen importlib._bootstrap_external>", line 783, in exec_module
  File "<frozen importlib._bootstrap>", line 219, in _call_with_frames_removed
  File "/home/ubuntu/backend/xxswl-backend/news/urls.py", line 2, in <module>
    from . import views
  File "/home/ubuntu/backend/xxswl-backend/news/views.py", line 10, in <module>
    from heatmap.dataGenerator import data_generator_ids
  File "/home/ubuntu/backend/xxswl-backend/heatmap/dataGenerator.py", line 24
SyntaxError: (unicode error) 'utf-8' codec can't decode byte 0xa3 in position 7: invalid start byte
/home/ubuntu/backend/xxswl-backend/heatmap/dataGenerator.py changed, reloading.
Performing system checks...

Watching for file changes with StatReloader
Exception in thread django-main-thread:
Traceback (most recent call last):
  File "/usr/lib/python3.8/threading.py", line 932, in _bootstrap_inner
    self.run()
  File "/usr/lib/python3.8/threading.py", line 870, in run
    self._target(*self._args, **self._kwargs)
  File "/home/ubuntu/.local/lib/python3.8/site-packages/django/utils/autoreload.py", line 53, in wrapper
    fn(*args, **kwargs)
  File "/home/ubuntu/.local/lib/python3.8/site-packages/django/core/management/commands/runserver.py", line 118, in inner_run
    self.check(display_num_errors=True)
  File "/home/ubuntu/.local/lib/python3.8/site-packages/django/core/management/base.py", line 392, in check
    all_issues = checks.run_checks(
  File "/home/ubuntu/.local/lib/python3.8/site-packages/django/core/checks/registry.py", line 70, in run_checks
    new_errors = check(app_configs=app_configs, databases=databases)
  File "/home/ubuntu/.local/lib/python3.8/site-packages/django/core/checks/urls.py", line 13, in check_url_config
    return check_resolver(resolver)
  File "/home/ubuntu/.local/lib/python3.8/site-packages/django/core/checks/urls.py", line 23, in check_resolver
    return check_method()
  File "/home/ubuntu/.local/lib/python3.8/site-packages/django/urls/resolvers.py", line 408, in check
    for pattern in self.url_patterns:
  File "/home/ubuntu/.local/lib/python3.8/site-packages/django/utils/functional.py", line 48, in __get__
    res = instance.__dict__[self.name] = self.func(instance)
  File "/home/ubuntu/.local/lib/python3.8/site-packages/django/urls/resolvers.py", line 589, in url_patterns
    patterns = getattr(self.urlconf_module, "urlpatterns", self.urlconf_module)
  File "/home/ubuntu/.local/lib/python3.8/site-packages/django/utils/functional.py", line 48, in __get__
    res = instance.__dict__[self.name] = self.func(instance)
  File "/home/ubuntu/.local/lib/python3.8/site-packages/django/urls/resolvers.py", line 582, in urlconf_module
    return import_module(self.urlconf_name)
  File "/usr/lib/python3.8/importlib/__init__.py", line 127, in import_module
    return _bootstrap._gcd_import(name[level:], package, level)
  File "<frozen importlib._bootstrap>", line 1014, in _gcd_import
  File "<frozen importlib._bootstrap>", line 991, in _find_and_load
  File "<frozen importlib._bootstrap>", line 975, in _find_and_load_unlocked
  File "<frozen importlib._bootstrap>", line 671, in _load_unlocked
  File "<frozen importlib._bootstrap_external>", line 783, in exec_module
  File "<frozen importlib._bootstrap>", line 219, in _call_with_frames_removed
  File "/home/ubuntu/backend/xxswl-backend/xxswl/urls.py", line 21, in <module>
    path('news/',include('news.urls')),
  File "/home/ubuntu/.local/lib/python3.8/site-packages/django/urls/conf.py", line 34, in include
    urlconf_module = import_module(urlconf_module)
  File "/usr/lib/python3.8/importlib/__init__.py", line 127, in import_module
    return _bootstrap._gcd_import(name[level:], package, level)
  File "<frozen importlib._bootstrap>", line 1014, in _gcd_import
  File "<frozen importlib._bootstrap>", line 991, in _find_and_load
  File "<frozen importlib._bootstrap>", line 975, in _find_and_load_unlocked
  File "<frozen importlib._bootstrap>", line 671, in _load_unlocked
  File "<frozen importlib._bootstrap_external>", line 783, in exec_module
  File "<frozen importlib._bootstrap>", line 219, in _call_with_frames_removed
  File "/home/ubuntu/backend/xxswl-backend/news/urls.py", line 2, in <module>
    from . import views
  File "/home/ubuntu/backend/xxswl-backend/news/views.py", line 10, in <module>
    from heatmap.dataGenerator import data_generator_ids
  File "/home/ubuntu/backend/xxswl-backend/heatmap/dataGenerator.py", line 24
SyntaxError: (unicode error) 'utf-8' codec can't decode byte 0xa3 in position 4: invalid start byte
/home/ubuntu/backend/xxswl-backend/heatmap/dataGenerator.py changed, reloading.
Performing system checks...

Watching for file changes with StatReloader
Exception in thread django-main-thread:
Traceback (most recent call last):
  File "/usr/lib/python3.8/threading.py", line 932, in _bootstrap_inner
    self.run()
  File "/usr/lib/python3.8/threading.py", line 870, in run
    self._target(*self._args, **self._kwargs)
  File "/home/ubuntu/.local/lib/python3.8/site-packages/django/utils/autoreload.py", line 53, in wrapper
    fn(*args, **kwargs)
  File "/home/ubuntu/.local/lib/python3.8/site-packages/django/core/management/commands/runserver.py", line 118, in inner_run
    self.check(display_num_errors=True)
  File "/home/ubuntu/.local/lib/python3.8/site-packages/django/core/management/base.py", line 392, in check
    all_issues = checks.run_checks(
  File "/home/ubuntu/.local/lib/python3.8/site-packages/django/core/checks/registry.py", line 70, in run_checks
    new_errors = check(app_configs=app_configs, databases=databases)
  File "/home/ubuntu/.local/lib/python3.8/site-packages/django/core/checks/urls.py", line 13, in check_url_config
    return check_resolver(resolver)
  File "/home/ubuntu/.local/lib/python3.8/site-packages/django/core/checks/urls.py", line 23, in check_resolver
    return check_method()
  File "/home/ubuntu/.local/lib/python3.8/site-packages/django/urls/resolvers.py", line 408, in check
    for pattern in self.url_patterns:
  File "/home/ubuntu/.local/lib/python3.8/site-packages/django/utils/functional.py", line 48, in __get__
    res = instance.__dict__[self.name] = self.func(instance)
  File "/home/ubuntu/.local/lib/python3.8/site-packages/django/urls/resolvers.py", line 589, in url_patterns
    patterns = getattr(self.urlconf_module, "urlpatterns", self.urlconf_module)
  File "/home/ubuntu/.local/lib/python3.8/site-packages/django/utils/functional.py", line 48, in __get__
    res = instance.__dict__[self.name] = self.func(instance)
  File "/home/ubuntu/.local/lib/python3.8/site-packages/django/urls/resolvers.py", line 582, in urlconf_module
    return import_module(self.urlconf_name)
  File "/usr/lib/python3.8/importlib/__init__.py", line 127, in import_module
    return _bootstrap._gcd_import(name[level:], package, level)
  File "<frozen importlib._bootstrap>", line 1014, in _gcd_import
  File "<frozen importlib._bootstrap>", line 991, in _find_and_load
  File "<frozen importlib._bootstrap>", line 975, in _find_and_load_unlocked
  File "<frozen importlib._bootstrap>", line 671, in _load_unlocked
  File "<frozen importlib._bootstrap_external>", line 783, in exec_module
  File "<frozen importlib._bootstrap>", line 219, in _call_with_frames_removed
  File "/home/ubuntu/backend/xxswl-backend/xxswl/urls.py", line 21, in <module>
    path('news/',include('news.urls')),
  File "/home/ubuntu/.local/lib/python3.8/site-packages/django/urls/conf.py", line 34, in include
    urlconf_module = import_module(urlconf_module)
  File "/usr/lib/python3.8/importlib/__init__.py", line 127, in import_module
    return _bootstrap._gcd_import(name[level:], package, level)
  File "<frozen importlib._bootstrap>", line 1014, in _gcd_import
  File "<frozen importlib._bootstrap>", line 991, in _find_and_load
  File "<frozen importlib._bootstrap>", line 975, in _find_and_load_unlocked
  File "<frozen importlib._bootstrap>", line 671, in _load_unlocked
  File "<frozen importlib._bootstrap_external>", line 783, in exec_module
  File "<frozen importlib._bootstrap>", line 219, in _call_with_frames_removed
  File "/home/ubuntu/backend/xxswl-backend/news/urls.py", line 2, in <module>
    from . import views
  File "/home/ubuntu/backend/xxswl-backend/news/views.py", line 10, in <module>
    from heatmap.dataGenerator import data_generator_ids
  File "/home/ubuntu/backend/xxswl-backend/heatmap/dataGenerator.py", line 24
SyntaxError: (unicode error) 'utf-8' codec can't decode byte 0xa3 in position 1: invalid start byte
/home/ubuntu/backend/xxswl-backend/heatmap/dataGenerator.py changed, reloading.
Performing system checks...

Watching for file changes with StatReloader
Exception in thread django-main-thread:
Traceback (most recent call last):
  File "/usr/lib/python3.8/threading.py", line 932, in _bootstrap_inner
    self.run()
  File "/usr/lib/python3.8/threading.py", line 870, in run
    self._target(*self._args, **self._kwargs)
  File "/home/ubuntu/.local/lib/python3.8/site-packages/django/utils/autoreload.py", line 53, in wrapper
    fn(*args, **kwargs)
  File "/home/ubuntu/.local/lib/python3.8/site-packages/django/core/management/commands/runserver.py", line 118, in inner_run
    self.check(display_num_errors=True)
  File "/home/ubuntu/.local/lib/python3.8/site-packages/django/core/management/base.py", line 392, in check
    all_issues = checks.run_checks(
  File "/home/ubuntu/.local/lib/python3.8/site-packages/django/core/checks/registry.py", line 70, in run_checks
    new_errors = check(app_configs=app_configs, databases=databases)
  File "/home/ubuntu/.local/lib/python3.8/site-packages/django/core/checks/urls.py", line 13, in check_url_config
    return check_resolver(resolver)
  File "/home/ubuntu/.local/lib/python3.8/site-packages/django/core/checks/urls.py", line 23, in check_resolver
    return check_method()
  File "/home/ubuntu/.local/lib/python3.8/site-packages/django/urls/resolvers.py", line 408, in check
    for pattern in self.url_patterns:
  File "/home/ubuntu/.local/lib/python3.8/site-packages/django/utils/functional.py", line 48, in __get__
    res = instance.__dict__[self.name] = self.func(instance)
  File "/home/ubuntu/.local/lib/python3.8/site-packages/django/urls/resolvers.py", line 589, in url_patterns
    patterns = getattr(self.urlconf_module, "urlpatterns", self.urlconf_module)
  File "/home/ubuntu/.local/lib/python3.8/site-packages/django/utils/functional.py", line 48, in __get__
    res = instance.__dict__[self.name] = self.func(instance)
  File "/home/ubuntu/.local/lib/python3.8/site-packages/django/urls/resolvers.py", line 582, in urlconf_module
    return import_module(self.urlconf_name)
  File "/usr/lib/python3.8/importlib/__init__.py", line 127, in import_module
    return _bootstrap._gcd_import(name[level:], package, level)
  File "<frozen importlib._bootstrap>", line 1014, in _gcd_import
  File "<frozen importlib._bootstrap>", line 991, in _find_and_load
  File "<frozen importlib._bootstrap>", line 975, in _find_and_load_unlocked
  File "<frozen importlib._bootstrap>", line 671, in _load_unlocked
  File "<frozen importlib._bootstrap_external>", line 783, in exec_module
  File "<frozen importlib._bootstrap>", line 219, in _call_with_frames_removed
  File "/home/ubuntu/backend/xxswl-backend/xxswl/urls.py", line 21, in <module>
    path('news/',include('news.urls')),
  File "/home/ubuntu/.local/lib/python3.8/site-packages/django/urls/conf.py", line 34, in include
    urlconf_module = import_module(urlconf_module)
  File "/usr/lib/python3.8/importlib/__init__.py", line 127, in import_module
    return _bootstrap._gcd_import(name[level:], package, level)
  File "<frozen importlib._bootstrap>", line 1014, in _gcd_import
  File "<frozen importlib._bootstrap>", line 991, in _find_and_load
  File "<frozen importlib._bootstrap>", line 975, in _find_and_load_unlocked
  File "<frozen importlib._bootstrap>", line 671, in _load_unlocked
  File "<frozen importlib._bootstrap_external>", line 783, in exec_module
  File "<frozen importlib._bootstrap>", line 219, in _call_with_frames_removed
  File "/home/ubuntu/backend/xxswl-backend/news/urls.py", line 2, in <module>
    from . import views
  File "/home/ubuntu/backend/xxswl-backend/news/views.py", line 10, in <module>
    from heatmap.dataGenerator import data_generator_ids
  File "/home/ubuntu/backend/xxswl-backend/heatmap/dataGenerator.py", line 24
SyntaxError: (unicode error) 'utf-8' codec can't decode byte 0xa3 in position 1: invalid start byte
/home/ubuntu/backend/xxswl-backend/heatmap/dataGenerator.py changed, reloading.
Performing system checks...

Watching for file changes with StatReloader
Exception in thread django-main-thread:
Traceback (most recent call last):
  File "/usr/lib/python3.8/threading.py", line 932, in _bootstrap_inner
    self.run()
  File "/usr/lib/python3.8/threading.py", line 870, in run
    self._target(*self._args, **self._kwargs)
  File "/home/ubuntu/.local/lib/python3.8/site-packages/django/utils/autoreload.py", line 53, in wrapper
    fn(*args, **kwargs)
  File "/home/ubuntu/.local/lib/python3.8/site-packages/django/core/management/commands/runserver.py", line 118, in inner_run
    self.check(display_num_errors=True)
  File "/home/ubuntu/.local/lib/python3.8/site-packages/django/core/management/base.py", line 392, in check
    all_issues = checks.run_checks(
  File "/home/ubuntu/.local/lib/python3.8/site-packages/django/core/checks/registry.py", line 70, in run_checks
    new_errors = check(app_configs=app_configs, databases=databases)
  File "/home/ubuntu/.local/lib/python3.8/site-packages/django/core/checks/urls.py", line 13, in check_url_config
    return check_resolver(resolver)
  File "/home/ubuntu/.local/lib/python3.8/site-packages/django/core/checks/urls.py", line 23, in check_resolver
    return check_method()
  File "/home/ubuntu/.local/lib/python3.8/site-packages/django/urls/resolvers.py", line 408, in check
    for pattern in self.url_patterns:
  File "/home/ubuntu/.local/lib/python3.8/site-packages/django/utils/functional.py", line 48, in __get__
    res = instance.__dict__[self.name] = self.func(instance)
  File "/home/ubuntu/.local/lib/python3.8/site-packages/django/urls/resolvers.py", line 589, in url_patterns
    patterns = getattr(self.urlconf_module, "urlpatterns", self.urlconf_module)
  File "/home/ubuntu/.local/lib/python3.8/site-packages/django/utils/functional.py", line 48, in __get__
    res = instance.__dict__[self.name] = self.func(instance)
  File "/home/ubuntu/.local/lib/python3.8/site-packages/django/urls/resolvers.py", line 582, in urlconf_module
    return import_module(self.urlconf_name)
  File "/usr/lib/python3.8/importlib/__init__.py", line 127, in import_module
    return _bootstrap._gcd_import(name[level:], package, level)
  File "<frozen importlib._bootstrap>", line 1014, in _gcd_import
  File "<frozen importlib._bootstrap>", line 991, in _find_and_load
  File "<frozen importlib._bootstrap>", line 975, in _find_and_load_unlocked
  File "<frozen importlib._bootstrap>", line 671, in _load_unlocked
  File "<frozen importlib._bootstrap_external>", line 783, in exec_module
  File "<frozen importlib._bootstrap>", line 219, in _call_with_frames_removed
  File "/home/ubuntu/backend/xxswl-backend/xxswl/urls.py", line 21, in <module>
    path('news/',include('news.urls')),
  File "/home/ubuntu/.local/lib/python3.8/site-packages/django/urls/conf.py", line 34, in include
    urlconf_module = import_module(urlconf_module)
  File "/usr/lib/python3.8/importlib/__init__.py", line 127, in import_module
    return _bootstrap._gcd_import(name[level:], package, level)
  File "<frozen importlib._bootstrap>", line 1014, in _gcd_import
  File "<frozen importlib._bootstrap>", line 991, in _find_and_load
  File "<frozen importlib._bootstrap>", line 975, in _find_and_load_unlocked
  File "<frozen importlib._bootstrap>", line 671, in _load_unlocked
  File "<frozen importlib._bootstrap_external>", line 783, in exec_module
  File "<frozen importlib._bootstrap>", line 219, in _call_with_frames_removed
  File "/home/ubuntu/backend/xxswl-backend/news/urls.py", line 2, in <module>
    from . import views
  File "/home/ubuntu/backend/xxswl-backend/news/views.py", line 10, in <module>
    from heatmap.dataGenerator import data_generator_ids
  File "/home/ubuntu/backend/xxswl-backend/heatmap/dataGenerator.py", line 24
SyntaxError: (unicode error) 'utf-8' codec can't decode byte 0xa1 in position 1: invalid start byte
/home/ubuntu/backend/xxswl-backend/heatmap/dataGenerator.py changed, reloading.
Performing system checks...

Watching for file changes with StatReloader
Exception in thread django-main-thread:
Traceback (most recent call last):
  File "/usr/lib/python3.8/threading.py", line 932, in _bootstrap_inner
    self.run()
  File "/usr/lib/python3.8/threading.py", line 870, in run
    self._target(*self._args, **self._kwargs)
  File "/home/ubuntu/.local/lib/python3.8/site-packages/django/utils/autoreload.py", line 53, in wrapper
    fn(*args, **kwargs)
  File "/home/ubuntu/.local/lib/python3.8/site-packages/django/core/management/commands/runserver.py", line 118, in inner_run
    self.check(display_num_errors=True)
  File "/home/ubuntu/.local/lib/python3.8/site-packages/django/core/management/base.py", line 392, in check
    all_issues = checks.run_checks(
  File "/home/ubuntu/.local/lib/python3.8/site-packages/django/core/checks/registry.py", line 70, in run_checks
    new_errors = check(app_configs=app_configs, databases=databases)
  File "/home/ubuntu/.local/lib/python3.8/site-packages/django/core/checks/urls.py", line 13, in check_url_config
    return check_resolver(resolver)
  File "/home/ubuntu/.local/lib/python3.8/site-packages/django/core/checks/urls.py", line 23, in check_resolver
    return check_method()
  File "/home/ubuntu/.local/lib/python3.8/site-packages/django/urls/resolvers.py", line 408, in check
    for pattern in self.url_patterns:
  File "/home/ubuntu/.local/lib/python3.8/site-packages/django/utils/functional.py", line 48, in __get__
    res = instance.__dict__[self.name] = self.func(instance)
  File "/home/ubuntu/.local/lib/python3.8/site-packages/django/urls/resolvers.py", line 589, in url_patterns
    patterns = getattr(self.urlconf_module, "urlpatterns", self.urlconf_module)
  File "/home/ubuntu/.local/lib/python3.8/site-packages/django/utils/functional.py", line 48, in __get__
    res = instance.__dict__[self.name] = self.func(instance)
  File "/home/ubuntu/.local/lib/python3.8/site-packages/django/urls/resolvers.py", line 582, in urlconf_module
    return import_module(self.urlconf_name)
  File "/usr/lib/python3.8/importlib/__init__.py", line 127, in import_module
    return _bootstrap._gcd_import(name[level:], package, level)
  File "<frozen importlib._bootstrap>", line 1014, in _gcd_import
  File "<frozen importlib._bootstrap>", line 991, in _find_and_load
  File "<frozen importlib._bootstrap>", line 975, in _find_and_load_unlocked
  File "<frozen importlib._bootstrap>", line 671, in _load_unlocked
  File "<frozen importlib._bootstrap_external>", line 783, in exec_module
  File "<frozen importlib._bootstrap>", line 219, in _call_with_frames_removed
  File "/home/ubuntu/backend/xxswl-backend/xxswl/urls.py", line 21, in <module>
    path('news/',include('news.urls')),
  File "/home/ubuntu/.local/lib/python3.8/site-packages/django/urls/conf.py", line 34, in include
    urlconf_module = import_module(urlconf_module)
  File "/usr/lib/python3.8/importlib/__init__.py", line 127, in import_module
    return _bootstrap._gcd_import(name[level:], package, level)
  File "<frozen importlib._bootstrap>", line 1014, in _gcd_import
  File "<frozen importlib._bootstrap>", line 991, in _find_and_load
  File "<frozen importlib._bootstrap>", line 975, in _find_and_load_unlocked
  File "<frozen importlib._bootstrap>", line 671, in _load_unlocked
  File "<frozen importlib._bootstrap_external>", line 783, in exec_module
  File "<frozen importlib._bootstrap>", line 219, in _call_with_frames_removed
  File "/home/ubuntu/backend/xxswl-backend/news/urls.py", line 2, in <module>
    from . import views
  File "/home/ubuntu/backend/xxswl-backend/news/views.py", line 10, in <module>
    from heatmap.dataGenerator import data_generator_ids
  File "/home/ubuntu/backend/xxswl-backend/heatmap/dataGenerator.py", line 26
SyntaxError: (unicode error) 'utf-8' codec can't decode byte 0xa1 in position 1: invalid start byte
/home/ubuntu/backend/xxswl-backend/heatmap/dataGenerator.py changed, reloading.
Performing system checks...

Watching for file changes with StatReloader
Exception in thread django-main-thread:
Traceback (most recent call last):
  File "/usr/lib/python3.8/threading.py", line 932, in _bootstrap_inner
    self.run()
  File "/usr/lib/python3.8/threading.py", line 870, in run
    self._target(*self._args, **self._kwargs)
  File "/home/ubuntu/.local/lib/python3.8/site-packages/django/utils/autoreload.py", line 53, in wrapper
    fn(*args, **kwargs)
  File "/home/ubuntu/.local/lib/python3.8/site-packages/django/core/management/commands/runserver.py", line 118, in inner_run
    self.check(display_num_errors=True)
  File "/home/ubuntu/.local/lib/python3.8/site-packages/django/core/management/base.py", line 392, in check
    all_issues = checks.run_checks(
  File "/home/ubuntu/.local/lib/python3.8/site-packages/django/core/checks/registry.py", line 70, in run_checks
    new_errors = check(app_configs=app_configs, databases=databases)
  File "/home/ubuntu/.local/lib/python3.8/site-packages/django/core/checks/urls.py", line 13, in check_url_config
    return check_resolver(resolver)
  File "/home/ubuntu/.local/lib/python3.8/site-packages/django/core/checks/urls.py", line 23, in check_resolver
    return check_method()
  File "/home/ubuntu/.local/lib/python3.8/site-packages/django/urls/resolvers.py", line 408, in check
    for pattern in self.url_patterns:
  File "/home/ubuntu/.local/lib/python3.8/site-packages/django/utils/functional.py", line 48, in __get__
    res = instance.__dict__[self.name] = self.func(instance)
  File "/home/ubuntu/.local/lib/python3.8/site-packages/django/urls/resolvers.py", line 589, in url_patterns
    patterns = getattr(self.urlconf_module, "urlpatterns", self.urlconf_module)
  File "/home/ubuntu/.local/lib/python3.8/site-packages/django/utils/functional.py", line 48, in __get__
    res = instance.__dict__[self.name] = self.func(instance)
  File "/home/ubuntu/.local/lib/python3.8/site-packages/django/urls/resolvers.py", line 582, in urlconf_module
    return import_module(self.urlconf_name)
  File "/usr/lib/python3.8/importlib/__init__.py", line 127, in import_module
    return _bootstrap._gcd_import(name[level:], package, level)
  File "<frozen importlib._bootstrap>", line 1014, in _gcd_import
  File "<frozen importlib._bootstrap>", line 991, in _find_and_load
  File "<frozen importlib._bootstrap>", line 975, in _find_and_load_unlocked
  File "<frozen importlib._bootstrap>", line 671, in _load_unlocked
  File "<frozen importlib._bootstrap_external>", line 783, in exec_module
  File "<frozen importlib._bootstrap>", line 219, in _call_with_frames_removed
  File "/home/ubuntu/backend/xxswl-backend/xxswl/urls.py", line 21, in <module>
    path('news/',include('news.urls')),
  File "/home/ubuntu/.local/lib/python3.8/site-packages/django/urls/conf.py", line 34, in include
    urlconf_module = import_module(urlconf_module)
  File "/usr/lib/python3.8/importlib/__init__.py", line 127, in import_module
    return _bootstrap._gcd_import(name[level:], package, level)
  File "<frozen importlib._bootstrap>", line 1014, in _gcd_import
  File "<frozen importlib._bootstrap>", line 991, in _find_and_load
  File "<frozen importlib._bootstrap>", line 975, in _find_and_load_unlocked
  File "<frozen importlib._bootstrap>", line 671, in _load_unlocked
  File "<frozen importlib._bootstrap_external>", line 783, in exec_module
  File "<frozen importlib._bootstrap>", line 219, in _call_with_frames_removed
  File "/home/ubuntu/backend/xxswl-backend/news/urls.py", line 2, in <module>
    from . import views
  File "/home/ubuntu/backend/xxswl-backend/news/views.py", line 10, in <module>
    from heatmap.dataGenerator import data_generator_ids
  File "/home/ubuntu/backend/xxswl-backend/heatmap/dataGenerator.py", line 26
SyntaxError: (unicode error) 'utf-8' codec can't decode byte 0xa1 in position 1: invalid start byte
/home/ubuntu/backend/xxswl-backend/heatmap/dataGenerator.py changed, reloading.
Performing system checks...

Watching for file changes with StatReloader
Exception in thread django-main-thread:
Traceback (most recent call last):
  File "/usr/lib/python3.8/threading.py", line 932, in _bootstrap_inner
    self.run()
  File "/usr/lib/python3.8/threading.py", line 870, in run
    self._target(*self._args, **self._kwargs)
  File "/home/ubuntu/.local/lib/python3.8/site-packages/django/utils/autoreload.py", line 53, in wrapper
    fn(*args, **kwargs)
  File "/home/ubuntu/.local/lib/python3.8/site-packages/django/core/management/commands/runserver.py", line 118, in inner_run
    self.check(display_num_errors=True)
  File "/home/ubuntu/.local/lib/python3.8/site-packages/django/core/management/base.py", line 392, in check
    all_issues = checks.run_checks(
  File "/home/ubuntu/.local/lib/python3.8/site-packages/django/core/checks/registry.py", line 70, in run_checks
    new_errors = check(app_configs=app_configs, databases=databases)
  File "/home/ubuntu/.local/lib/python3.8/site-packages/django/core/checks/urls.py", line 13, in check_url_config
    return check_resolver(resolver)
  File "/home/ubuntu/.local/lib/python3.8/site-packages/django/core/checks/urls.py", line 23, in check_resolver
    return check_method()
  File "/home/ubuntu/.local/lib/python3.8/site-packages/django/urls/resolvers.py", line 408, in check
    for pattern in self.url_patterns:
  File "/home/ubuntu/.local/lib/python3.8/site-packages/django/utils/functional.py", line 48, in __get__
    res = instance.__dict__[self.name] = self.func(instance)
  File "/home/ubuntu/.local/lib/python3.8/site-packages/django/urls/resolvers.py", line 589, in url_patterns
    patterns = getattr(self.urlconf_module, "urlpatterns", self.urlconf_module)
  File "/home/ubuntu/.local/lib/python3.8/site-packages/django/utils/functional.py", line 48, in __get__
    res = instance.__dict__[self.name] = self.func(instance)
  File "/home/ubuntu/.local/lib/python3.8/site-packages/django/urls/resolvers.py", line 582, in urlconf_module
    return import_module(self.urlconf_name)
  File "/usr/lib/python3.8/importlib/__init__.py", line 127, in import_module
    return _bootstrap._gcd_import(name[level:], package, level)
  File "<frozen importlib._bootstrap>", line 1014, in _gcd_import
  File "<frozen importlib._bootstrap>", line 991, in _find_and_load
  File "<frozen importlib._bootstrap>", line 975, in _find_and_load_unlocked
  File "<frozen importlib._bootstrap>", line 671, in _load_unlocked
  File "<frozen importlib._bootstrap_external>", line 783, in exec_module
  File "<frozen importlib._bootstrap>", line 219, in _call_with_frames_removed
  File "/home/ubuntu/backend/xxswl-backend/xxswl/urls.py", line 21, in <module>
    path('news/',include('news.urls')),
  File "/home/ubuntu/.local/lib/python3.8/site-packages/django/urls/conf.py", line 34, in include
    urlconf_module = import_module(urlconf_module)
  File "/usr/lib/python3.8/importlib/__init__.py", line 127, in import_module
    return _bootstrap._gcd_import(name[level:], package, level)
  File "<frozen importlib._bootstrap>", line 1014, in _gcd_import
  File "<frozen importlib._bootstrap>", line 991, in _find_and_load
  File "<frozen importlib._bootstrap>", line 975, in _find_and_load_unlocked
  File "<frozen importlib._bootstrap>", line 671, in _load_unlocked
  File "<frozen importlib._bootstrap_external>", line 783, in exec_module
  File "<frozen importlib._bootstrap>", line 219, in _call_with_frames_removed
  File "/home/ubuntu/backend/xxswl-backend/news/urls.py", line 2, in <module>
    from . import views
  File "/home/ubuntu/backend/xxswl-backend/news/views.py", line 10, in <module>
    from heatmap.dataGenerator import data_generator_ids
  File "/home/ubuntu/backend/xxswl-backend/heatmap/dataGenerator.py", line 26
SyntaxError: (unicode error) 'utf-8' codec can't decode byte 0xa3 in position 1: invalid start byte
/home/ubuntu/backend/xxswl-backend/heatmap/dataGenerator.py changed, reloading.
Performing system checks...

Watching for file changes with StatReloader
Exception in thread django-main-thread:
Traceback (most recent call last):
  File "/usr/lib/python3.8/threading.py", line 932, in _bootstrap_inner
    self.run()
  File "/usr/lib/python3.8/threading.py", line 870, in run
    self._target(*self._args, **self._kwargs)
  File "/home/ubuntu/.local/lib/python3.8/site-packages/django/utils/autoreload.py", line 53, in wrapper
    fn(*args, **kwargs)
  File "/home/ubuntu/.local/lib/python3.8/site-packages/django/core/management/commands/runserver.py", line 118, in inner_run
    self.check(display_num_errors=True)
  File "/home/ubuntu/.local/lib/python3.8/site-packages/django/core/management/base.py", line 392, in check
    all_issues = checks.run_checks(
  File "/home/ubuntu/.local/lib/python3.8/site-packages/django/core/checks/registry.py", line 70, in run_checks
    new_errors = check(app_configs=app_configs, databases=databases)
  File "/home/ubuntu/.local/lib/python3.8/site-packages/django/core/checks/urls.py", line 13, in check_url_config
    return check_resolver(resolver)
  File "/home/ubuntu/.local/lib/python3.8/site-packages/django/core/checks/urls.py", line 23, in check_resolver
    return check_method()
  File "/home/ubuntu/.local/lib/python3.8/site-packages/django/urls/resolvers.py", line 408, in check
    for pattern in self.url_patterns:
  File "/home/ubuntu/.local/lib/python3.8/site-packages/django/utils/functional.py", line 48, in __get__
    res = instance.__dict__[self.name] = self.func(instance)
  File "/home/ubuntu/.local/lib/python3.8/site-packages/django/urls/resolvers.py", line 589, in url_patterns
    patterns = getattr(self.urlconf_module, "urlpatterns", self.urlconf_module)
  File "/home/ubuntu/.local/lib/python3.8/site-packages/django/utils/functional.py", line 48, in __get__
    res = instance.__dict__[self.name] = self.func(instance)
  File "/home/ubuntu/.local/lib/python3.8/site-packages/django/urls/resolvers.py", line 582, in urlconf_module
    return import_module(self.urlconf_name)
  File "/usr/lib/python3.8/importlib/__init__.py", line 127, in import_module
    return _bootstrap._gcd_import(name[level:], package, level)
  File "<frozen importlib._bootstrap>", line 1014, in _gcd_import
  File "<frozen importlib._bootstrap>", line 991, in _find_and_load
  File "<frozen importlib._bootstrap>", line 975, in _find_and_load_unlocked
  File "<frozen importlib._bootstrap>", line 671, in _load_unlocked
  File "<frozen importlib._bootstrap_external>", line 783, in exec_module
  File "<frozen importlib._bootstrap>", line 219, in _call_with_frames_removed
  File "/home/ubuntu/backend/xxswl-backend/xxswl/urls.py", line 21, in <module>
    path('news/',include('news.urls')),
  File "/home/ubuntu/.local/lib/python3.8/site-packages/django/urls/conf.py", line 34, in include
    urlconf_module = import_module(urlconf_module)
  File "/usr/lib/python3.8/importlib/__init__.py", line 127, in import_module
    return _bootstrap._gcd_import(name[level:], package, level)
  File "<frozen importlib._bootstrap>", line 1014, in _gcd_import
  File "<frozen importlib._bootstrap>", line 991, in _find_and_load
  File "<frozen importlib._bootstrap>", line 975, in _find_and_load_unlocked
  File "<frozen importlib._bootstrap>", line 671, in _load_unlocked
  File "<frozen importlib._bootstrap_external>", line 783, in exec_module
  File "<frozen importlib._bootstrap>", line 219, in _call_with_frames_removed
  File "/home/ubuntu/backend/xxswl-backend/news/urls.py", line 2, in <module>
    from . import views
  File "/home/ubuntu/backend/xxswl-backend/news/views.py", line 10, in <module>
    from heatmap.dataGenerator import data_generator_ids
  File "/home/ubuntu/backend/xxswl-backend/heatmap/dataGenerator.py", line 23
SyntaxError: (unicode error) 'utf-8' codec can't decode byte 0xa3 in position 66: invalid start byte
/home/ubuntu/backend/xxswl-backend/heatmap/dataGenerator.py changed, reloading.
Performing system checks...

Watching for file changes with StatReloader
Exception in thread django-main-thread:
Traceback (most recent call last):
  File "/usr/lib/python3.8/threading.py", line 932, in _bootstrap_inner
    self.run()
  File "/usr/lib/python3.8/threading.py", line 870, in run
    self._target(*self._args, **self._kwargs)
  File "/home/ubuntu/.local/lib/python3.8/site-packages/django/utils/autoreload.py", line 53, in wrapper
    fn(*args, **kwargs)
  File "/home/ubuntu/.local/lib/python3.8/site-packages/django/core/management/commands/runserver.py", line 118, in inner_run
    self.check(display_num_errors=True)
  File "/home/ubuntu/.local/lib/python3.8/site-packages/django/core/management/base.py", line 392, in check
    all_issues = checks.run_checks(
  File "/home/ubuntu/.local/lib/python3.8/site-packages/django/core/checks/registry.py", line 70, in run_checks
    new_errors = check(app_configs=app_configs, databases=databases)
  File "/home/ubuntu/.local/lib/python3.8/site-packages/django/core/checks/urls.py", line 13, in check_url_config
    return check_resolver(resolver)
  File "/home/ubuntu/.local/lib/python3.8/site-packages/django/core/checks/urls.py", line 23, in check_resolver
    return check_method()
  File "/home/ubuntu/.local/lib/python3.8/site-packages/django/urls/resolvers.py", line 408, in check
    for pattern in self.url_patterns:
  File "/home/ubuntu/.local/lib/python3.8/site-packages/django/utils/functional.py", line 48, in __get__
    res = instance.__dict__[self.name] = self.func(instance)
  File "/home/ubuntu/.local/lib/python3.8/site-packages/django/urls/resolvers.py", line 589, in url_patterns
    patterns = getattr(self.urlconf_module, "urlpatterns", self.urlconf_module)
  File "/home/ubuntu/.local/lib/python3.8/site-packages/django/utils/functional.py", line 48, in __get__
    res = instance.__dict__[self.name] = self.func(instance)
  File "/home/ubuntu/.local/lib/python3.8/site-packages/django/urls/resolvers.py", line 582, in urlconf_module
    return import_module(self.urlconf_name)
  File "/usr/lib/python3.8/importlib/__init__.py", line 127, in import_module
    return _bootstrap._gcd_import(name[level:], package, level)
  File "<frozen importlib._bootstrap>", line 1014, in _gcd_import
  File "<frozen importlib._bootstrap>", line 991, in _find_and_load
  File "<frozen importlib._bootstrap>", line 975, in _find_and_load_unlocked
  File "<frozen importlib._bootstrap>", line 671, in _load_unlocked
  File "<frozen importlib._bootstrap_external>", line 783, in exec_module
  File "<frozen importlib._bootstrap>", line 219, in _call_with_frames_removed
  File "/home/ubuntu/backend/xxswl-backend/xxswl/urls.py", line 21, in <module>
    path('news/',include('news.urls')),
  File "/home/ubuntu/.local/lib/python3.8/site-packages/django/urls/conf.py", line 34, in include
    urlconf_module = import_module(urlconf_module)
  File "/usr/lib/python3.8/importlib/__init__.py", line 127, in import_module
    return _bootstrap._gcd_import(name[level:], package, level)
  File "<frozen importlib._bootstrap>", line 1014, in _gcd_import
  File "<frozen importlib._bootstrap>", line 991, in _find_and_load
  File "<frozen importlib._bootstrap>", line 975, in _find_and_load_unlocked
  File "<frozen importlib._bootstrap>", line 671, in _load_unlocked
  File "<frozen importlib._bootstrap_external>", line 783, in exec_module
  File "<frozen importlib._bootstrap>", line 219, in _call_with_frames_removed
  File "/home/ubuntu/backend/xxswl-backend/news/urls.py", line 2, in <module>
    from . import views
  File "/home/ubuntu/backend/xxswl-backend/news/views.py", line 10, in <module>
    from heatmap.dataGenerator import data_generator_ids
  File "/home/ubuntu/backend/xxswl-backend/heatmap/dataGenerator.py", line 0
SyntaxError: unknown encoding: unicode
/home/ubuntu/backend/xxswl-backend/heatmap/dataGenerator.py changed, reloading.
Performing system checks...

Watching for file changes with StatReloader
Exception in thread django-main-thread:
Traceback (most recent call last):
  File "/usr/lib/python3.8/threading.py", line 932, in _bootstrap_inner
    self.run()
  File "/usr/lib/python3.8/threading.py", line 870, in run
    self._target(*self._args, **self._kwargs)
  File "/home/ubuntu/.local/lib/python3.8/site-packages/django/utils/autoreload.py", line 53, in wrapper
    fn(*args, **kwargs)
  File "/home/ubuntu/.local/lib/python3.8/site-packages/django/core/management/commands/runserver.py", line 118, in inner_run
    self.check(display_num_errors=True)
  File "/home/ubuntu/.local/lib/python3.8/site-packages/django/core/management/base.py", line 392, in check
    all_issues = checks.run_checks(
  File "/home/ubuntu/.local/lib/python3.8/site-packages/django/core/checks/registry.py", line 70, in run_checks
    new_errors = check(app_configs=app_configs, databases=databases)
  File "/home/ubuntu/.local/lib/python3.8/site-packages/django/core/checks/urls.py", line 13, in check_url_config
    return check_resolver(resolver)
  File "/home/ubuntu/.local/lib/python3.8/site-packages/django/core/checks/urls.py", line 23, in check_resolver
    return check_method()
  File "/home/ubuntu/.local/lib/python3.8/site-packages/django/urls/resolvers.py", line 408, in check
    for pattern in self.url_patterns:
  File "/home/ubuntu/.local/lib/python3.8/site-packages/django/utils/functional.py", line 48, in __get__
    res = instance.__dict__[self.name] = self.func(instance)
  File "/home/ubuntu/.local/lib/python3.8/site-packages/django/urls/resolvers.py", line 589, in url_patterns
    patterns = getattr(self.urlconf_module, "urlpatterns", self.urlconf_module)
  File "/home/ubuntu/.local/lib/python3.8/site-packages/django/utils/functional.py", line 48, in __get__
    res = instance.__dict__[self.name] = self.func(instance)
  File "/home/ubuntu/.local/lib/python3.8/site-packages/django/urls/resolvers.py", line 582, in urlconf_module
    return import_module(self.urlconf_name)
  File "/usr/lib/python3.8/importlib/__init__.py", line 127, in import_module
    return _bootstrap._gcd_import(name[level:], package, level)
  File "<frozen importlib._bootstrap>", line 1014, in _gcd_import
  File "<frozen importlib._bootstrap>", line 991, in _find_and_load
  File "<frozen importlib._bootstrap>", line 975, in _find_and_load_unlocked
  File "<frozen importlib._bootstrap>", line 671, in _load_unlocked
  File "<frozen importlib._bootstrap_external>", line 783, in exec_module
  File "<frozen importlib._bootstrap>", line 219, in _call_with_frames_removed
  File "/home/ubuntu/backend/xxswl-backend/xxswl/urls.py", line 21, in <module>
    path('news/',include('news.urls')),
  File "/home/ubuntu/.local/lib/python3.8/site-packages/django/urls/conf.py", line 34, in include
    urlconf_module = import_module(urlconf_module)
  File "/usr/lib/python3.8/importlib/__init__.py", line 127, in import_module
    return _bootstrap._gcd_import(name[level:], package, level)
  File "<frozen importlib._bootstrap>", line 1014, in _gcd_import
  File "<frozen importlib._bootstrap>", line 991, in _find_and_load
  File "<frozen importlib._bootstrap>", line 975, in _find_and_load_unlocked
  File "<frozen importlib._bootstrap>", line 671, in _load_unlocked
  File "<frozen importlib._bootstrap_external>", line 783, in exec_module
  File "<frozen importlib._bootstrap>", line 219, in _call_with_frames_removed
  File "/home/ubuntu/backend/xxswl-backend/news/urls.py", line 2, in <module>
    from . import views
  File "/home/ubuntu/backend/xxswl-backend/news/views.py", line 10, in <module>
    from heatmap.dataGenerator import data_generator_ids
  File "/home/ubuntu/backend/xxswl-backend/heatmap/dataGenerator.py", line 0
SyntaxError: 'gbk' codec can't decode byte 0xad in position 1237: illegal multibyte sequence
/home/ubuntu/backend/xxswl-backend/heatmap/dataGenerator.py changed, reloading.
Performing system checks...

Watching for file changes with StatReloader
Exception in thread django-main-thread:
Traceback (most recent call last):
  File "/usr/lib/python3.8/threading.py", line 932, in _bootstrap_inner
    self.run()
  File "/usr/lib/python3.8/threading.py", line 870, in run
    self._target(*self._args, **self._kwargs)
  File "/home/ubuntu/.local/lib/python3.8/site-packages/django/utils/autoreload.py", line 53, in wrapper
    fn(*args, **kwargs)
  File "/home/ubuntu/.local/lib/python3.8/site-packages/django/core/management/commands/runserver.py", line 118, in inner_run
    self.check(display_num_errors=True)
  File "/home/ubuntu/.local/lib/python3.8/site-packages/django/core/management/base.py", line 392, in check
    all_issues = checks.run_checks(
  File "/home/ubuntu/.local/lib/python3.8/site-packages/django/core/checks/registry.py", line 70, in run_checks
    new_errors = check(app_configs=app_configs, databases=databases)
  File "/home/ubuntu/.local/lib/python3.8/site-packages/django/core/checks/urls.py", line 13, in check_url_config
    return check_resolver(resolver)
  File "/home/ubuntu/.local/lib/python3.8/site-packages/django/core/checks/urls.py", line 23, in check_resolver
    return check_method()
  File "/home/ubuntu/.local/lib/python3.8/site-packages/django/urls/resolvers.py", line 408, in check
    for pattern in self.url_patterns:
  File "/home/ubuntu/.local/lib/python3.8/site-packages/django/utils/functional.py", line 48, in __get__
    res = instance.__dict__[self.name] = self.func(instance)
  File "/home/ubuntu/.local/lib/python3.8/site-packages/django/urls/resolvers.py", line 589, in url_patterns
    patterns = getattr(self.urlconf_module, "urlpatterns", self.urlconf_module)
  File "/home/ubuntu/.local/lib/python3.8/site-packages/django/utils/functional.py", line 48, in __get__
    res = instance.__dict__[self.name] = self.func(instance)
  File "/home/ubuntu/.local/lib/python3.8/site-packages/django/urls/resolvers.py", line 582, in urlconf_module
    return import_module(self.urlconf_name)
  File "/usr/lib/python3.8/importlib/__init__.py", line 127, in import_module
    return _bootstrap._gcd_import(name[level:], package, level)
  File "<frozen importlib._bootstrap>", line 1014, in _gcd_import
  File "<frozen importlib._bootstrap>", line 991, in _find_and_load
  File "<frozen importlib._bootstrap>", line 975, in _find_and_load_unlocked
  File "<frozen importlib._bootstrap>", line 671, in _load_unlocked
  File "<frozen importlib._bootstrap_external>", line 783, in exec_module
  File "<frozen importlib._bootstrap>", line 219, in _call_with_frames_removed
  File "/home/ubuntu/backend/xxswl-backend/xxswl/urls.py", line 21, in <module>
    path('news/',include('news.urls')),
  File "/home/ubuntu/.local/lib/python3.8/site-packages/django/urls/conf.py", line 34, in include
    urlconf_module = import_module(urlconf_module)
  File "/usr/lib/python3.8/importlib/__init__.py", line 127, in import_module
    return _bootstrap._gcd_import(name[level:], package, level)
  File "<frozen importlib._bootstrap>", line 1014, in _gcd_import
  File "<frozen importlib._bootstrap>", line 991, in _find_and_load
  File "<frozen importlib._bootstrap>", line 975, in _find_and_load_unlocked
  File "<frozen importlib._bootstrap>", line 671, in _load_unlocked
  File "<frozen importlib._bootstrap_external>", line 783, in exec_module
  File "<frozen importlib._bootstrap>", line 219, in _call_with_frames_removed
  File "/home/ubuntu/backend/xxswl-backend/news/urls.py", line 2, in <module>
    from . import views
  File "/home/ubuntu/backend/xxswl-backend/news/views.py", line 10, in <module>
    from heatmap.dataGenerator import data_generator_ids
  File "/home/ubuntu/backend/xxswl-backend/heatmap/dataGenerator.py", line 0
SyntaxError: 'gbk' codec can't decode byte 0xad in position 1220: illegal multibyte sequence
/home/ubuntu/backend/xxswl-backend/heatmap/dataGenerator.py changed, reloading.
Performing system checks...

Watching for file changes with StatReloader
Exception in thread django-main-thread:
Traceback (most recent call last):
  File "/usr/lib/python3.8/threading.py", line 932, in _bootstrap_inner
    self.run()
  File "/usr/lib/python3.8/threading.py", line 870, in run
    self._target(*self._args, **self._kwargs)
  File "/home/ubuntu/.local/lib/python3.8/site-packages/django/utils/autoreload.py", line 53, in wrapper
    fn(*args, **kwargs)
  File "/home/ubuntu/.local/lib/python3.8/site-packages/django/core/management/commands/runserver.py", line 118, in inner_run
    self.check(display_num_errors=True)
  File "/home/ubuntu/.local/lib/python3.8/site-packages/django/core/management/base.py", line 392, in check
    all_issues = checks.run_checks(
  File "/home/ubuntu/.local/lib/python3.8/site-packages/django/core/checks/registry.py", line 70, in run_checks
    new_errors = check(app_configs=app_configs, databases=databases)
  File "/home/ubuntu/.local/lib/python3.8/site-packages/django/core/checks/urls.py", line 13, in check_url_config
    return check_resolver(resolver)
  File "/home/ubuntu/.local/lib/python3.8/site-packages/django/core/checks/urls.py", line 23, in check_resolver
    return check_method()
  File "/home/ubuntu/.local/lib/python3.8/site-packages/django/urls/resolvers.py", line 408, in check
    for pattern in self.url_patterns:
  File "/home/ubuntu/.local/lib/python3.8/site-packages/django/utils/functional.py", line 48, in __get__
    res = instance.__dict__[self.name] = self.func(instance)
  File "/home/ubuntu/.local/lib/python3.8/site-packages/django/urls/resolvers.py", line 589, in url_patterns
    patterns = getattr(self.urlconf_module, "urlpatterns", self.urlconf_module)
  File "/home/ubuntu/.local/lib/python3.8/site-packages/django/utils/functional.py", line 48, in __get__
    res = instance.__dict__[self.name] = self.func(instance)
  File "/home/ubuntu/.local/lib/python3.8/site-packages/django/urls/resolvers.py", line 582, in urlconf_module
    return import_module(self.urlconf_name)
  File "/usr/lib/python3.8/importlib/__init__.py", line 127, in import_module
    return _bootstrap._gcd_import(name[level:], package, level)
  File "<frozen importlib._bootstrap>", line 1014, in _gcd_import
  File "<frozen importlib._bootstrap>", line 991, in _find_and_load
  File "<frozen importlib._bootstrap>", line 975, in _find_and_load_unlocked
  File "<frozen importlib._bootstrap>", line 671, in _load_unlocked
  File "<frozen importlib._bootstrap_external>", line 783, in exec_module
  File "<frozen importlib._bootstrap>", line 219, in _call_with_frames_removed
  File "/home/ubuntu/backend/xxswl-backend/xxswl/urls.py", line 21, in <module>
    path('news/',include('news.urls')),
  File "/home/ubuntu/.local/lib/python3.8/site-packages/django/urls/conf.py", line 34, in include
    urlconf_module = import_module(urlconf_module)
  File "/usr/lib/python3.8/importlib/__init__.py", line 127, in import_module
    return _bootstrap._gcd_import(name[level:], package, level)
  File "<frozen importlib._bootstrap>", line 1014, in _gcd_import
  File "<frozen importlib._bootstrap>", line 991, in _find_and_load
  File "<frozen importlib._bootstrap>", line 975, in _find_and_load_unlocked
  File "<frozen importlib._bootstrap>", line 671, in _load_unlocked
  File "<frozen importlib._bootstrap_external>", line 783, in exec_module
  File "<frozen importlib._bootstrap>", line 219, in _call_with_frames_removed
  File "/home/ubuntu/backend/xxswl-backend/news/urls.py", line 2, in <module>
    from . import views
  File "/home/ubuntu/backend/xxswl-backend/news/views.py", line 10, in <module>
    from heatmap.dataGenerator import data_generator_ids
  File "/home/ubuntu/backend/xxswl-backend/heatmap/dataGenerator.py", line 22
SyntaxError: (unicode error) 'utf-8' codec can't decode byte 0xa3 in position 66: invalid start byte
/home/ubuntu/backend/xxswl-backend/heatmap/dataGenerator.py changed, reloading.
Performing system checks...

Watching for file changes with StatReloader
Exception in thread django-main-thread:
Traceback (most recent call last):
  File "/usr/lib/python3.8/threading.py", line 932, in _bootstrap_inner
    self.run()
  File "/usr/lib/python3.8/threading.py", line 870, in run
    self._target(*self._args, **self._kwargs)
  File "/home/ubuntu/.local/lib/python3.8/site-packages/django/utils/autoreload.py", line 53, in wrapper
    fn(*args, **kwargs)
  File "/home/ubuntu/.local/lib/python3.8/site-packages/django/core/management/commands/runserver.py", line 118, in inner_run
    self.check(display_num_errors=True)
  File "/home/ubuntu/.local/lib/python3.8/site-packages/django/core/management/base.py", line 392, in check
    all_issues = checks.run_checks(
  File "/home/ubuntu/.local/lib/python3.8/site-packages/django/core/checks/registry.py", line 70, in run_checks
    new_errors = check(app_configs=app_configs, databases=databases)
  File "/home/ubuntu/.local/lib/python3.8/site-packages/django/core/checks/urls.py", line 13, in check_url_config
    return check_resolver(resolver)
  File "/home/ubuntu/.local/lib/python3.8/site-packages/django/core/checks/urls.py", line 23, in check_resolver
    return check_method()
  File "/home/ubuntu/.local/lib/python3.8/site-packages/django/urls/resolvers.py", line 408, in check
    for pattern in self.url_patterns:
  File "/home/ubuntu/.local/lib/python3.8/site-packages/django/utils/functional.py", line 48, in __get__
    res = instance.__dict__[self.name] = self.func(instance)
  File "/home/ubuntu/.local/lib/python3.8/site-packages/django/urls/resolvers.py", line 589, in url_patterns
    patterns = getattr(self.urlconf_module, "urlpatterns", self.urlconf_module)
  File "/home/ubuntu/.local/lib/python3.8/site-packages/django/utils/functional.py", line 48, in __get__
    res = instance.__dict__[self.name] = self.func(instance)
  File "/home/ubuntu/.local/lib/python3.8/site-packages/django/urls/resolvers.py", line 582, in urlconf_module
    return import_module(self.urlconf_name)
  File "/usr/lib/python3.8/importlib/__init__.py", line 127, in import_module
    return _bootstrap._gcd_import(name[level:], package, level)
  File "<frozen importlib._bootstrap>", line 1014, in _gcd_import
  File "<frozen importlib._bootstrap>", line 991, in _find_and_load
  File "<frozen importlib._bootstrap>", line 975, in _find_and_load_unlocked
  File "<frozen importlib._bootstrap>", line 671, in _load_unlocked
  File "<frozen importlib._bootstrap_external>", line 783, in exec_module
  File "<frozen importlib._bootstrap>", line 219, in _call_with_frames_removed
  File "/home/ubuntu/backend/xxswl-backend/xxswl/urls.py", line 21, in <module>
    path('news/',include('news.urls')),
  File "/home/ubuntu/.local/lib/python3.8/site-packages/django/urls/conf.py", line 34, in include
    urlconf_module = import_module(urlconf_module)
  File "/usr/lib/python3.8/importlib/__init__.py", line 127, in import_module
    return _bootstrap._gcd_import(name[level:], package, level)
  File "<frozen importlib._bootstrap>", line 1014, in _gcd_import
  File "<frozen importlib._bootstrap>", line 991, in _find_and_load
  File "<frozen importlib._bootstrap>", line 975, in _find_and_load_unlocked
  File "<frozen importlib._bootstrap>", line 671, in _load_unlocked
  File "<frozen importlib._bootstrap_external>", line 783, in exec_module
  File "<frozen importlib._bootstrap>", line 219, in _call_with_frames_removed
  File "/home/ubuntu/backend/xxswl-backend/news/urls.py", line 2, in <module>
    from . import views
  File "/home/ubuntu/backend/xxswl-backend/news/views.py", line 10, in <module>
    from heatmap.dataGenerator import data_generator_ids
  File "/home/ubuntu/backend/xxswl-backend/heatmap/dataGenerator.py", line 27
SyntaxError: (unicode error) 'utf-8' codec can't decode byte 0xb5 in position 0: invalid start byte
/home/ubuntu/backend/xxswl-backend/heatmap/dataGenerator.py changed, reloading.
Performing system checks...

Watching for file changes with StatReloader
/home/ubuntu/backend/xxswl-backend/heatmap/dataGenerator.py changed, reloading.
Performing system checks...

System check identified no issues (0 silenced).
November 04, 2020 - 17:49:49
Django version 3.1.1, using settings 'xxswl.settings'
Starting development server at http://0.0.0.0:30000/
Quit the server with CONTROL-C.
Watching for file changes with StatReloader
/home/ubuntu/backend/xxswl-backend/heatmap/dataGenerator.py changed, reloading.
Performing system checks...

System check identified no issues (0 silenced).
November 04, 2020 - 17:58:02
Django version 3.1.1, using settings 'xxswl.settings'
Starting development server at http://0.0.0.0:30000/
Quit the server with CONTROL-C.
Watching for file changes with StatReloader
Exception in thread django-main-thread:
Traceback (most recent call last):
  File "/usr/lib/python3.8/threading.py", line 932, in _bootstrap_inner
    self.run()
  File "/usr/lib/python3.8/threading.py", line 870, in run
    self._target(*self._args, **self._kwargs)
  File "/home/ubuntu/.local/lib/python3.8/site-packages/django/utils/autoreload.py", line 53, in wrapper
    fn(*args, **kwargs)
  File "/home/ubuntu/.local/lib/python3.8/site-packages/django/core/management/commands/runserver.py", line 118, in inner_run
    self.check(display_num_errors=True)
  File "/home/ubuntu/.local/lib/python3.8/site-packages/django/core/management/base.py", line 392, in check
    all_issues = checks.run_checks(
  File "/home/ubuntu/.local/lib/python3.8/site-packages/django/core/checks/registry.py", line 70, in run_checks
    new_errors = check(app_configs=app_configs, databases=databases)
  File "/home/ubuntu/.local/lib/python3.8/site-packages/django/core/checks/urls.py", line 13, in check_url_config
    return check_resolver(resolver)
  File "/home/ubuntu/.local/lib/python3.8/site-packages/django/core/checks/urls.py", line 23, in check_resolver
    return check_method()
  File "/home/ubuntu/.local/lib/python3.8/site-packages/django/urls/resolvers.py", line 408, in check
    for pattern in self.url_patterns:
  File "/home/ubuntu/.local/lib/python3.8/site-packages/django/utils/functional.py", line 48, in __get__
    res = instance.__dict__[self.name] = self.func(instance)
  File "/home/ubuntu/.local/lib/python3.8/site-packages/django/urls/resolvers.py", line 589, in url_patterns
    patterns = getattr(self.urlconf_module, "urlpatterns", self.urlconf_module)
  File "/home/ubuntu/.local/lib/python3.8/site-packages/django/utils/functional.py", line 48, in __get__
    res = instance.__dict__[self.name] = self.func(instance)
  File "/home/ubuntu/.local/lib/python3.8/site-packages/django/urls/resolvers.py", line 582, in urlconf_module
    return import_module(self.urlconf_name)
  File "/usr/lib/python3.8/importlib/__init__.py", line 127, in import_module
    return _bootstrap._gcd_import(name[level:], package, level)
  File "<frozen importlib._bootstrap>", line 1014, in _gcd_import
  File "<frozen importlib._bootstrap>", line 991, in _find_and_load
  File "<frozen importlib._bootstrap>", line 975, in _find_and_load_unlocked
  File "<frozen importlib._bootstrap>", line 671, in _load_unlocked
  File "<frozen importlib._bootstrap_external>", line 783, in exec_module
  File "<frozen importlib._bootstrap>", line 219, in _call_with_frames_removed
  File "/home/ubuntu/backend/xxswl-backend/xxswl/urls.py", line 21, in <module>
    path('news/',include('news.urls')),
  File "/home/ubuntu/.local/lib/python3.8/site-packages/django/urls/conf.py", line 34, in include
    urlconf_module = import_module(urlconf_module)
  File "/usr/lib/python3.8/importlib/__init__.py", line 127, in import_module
    return _bootstrap._gcd_import(name[level:], package, level)
  File "<frozen importlib._bootstrap>", line 1014, in _gcd_import
  File "<frozen importlib._bootstrap>", line 991, in _find_and_load
  File "<frozen importlib._bootstrap>", line 975, in _find_and_load_unlocked
  File "<frozen importlib._bootstrap>", line 671, in _load_unlocked
  File "<frozen importlib._bootstrap_external>", line 783, in exec_module
  File "<frozen importlib._bootstrap>", line 219, in _call_with_frames_removed
  File "/home/ubuntu/backend/xxswl-backend/news/urls.py", line 2, in <module>
    from . import views
  File "/home/ubuntu/backend/xxswl-backend/news/views.py", line 10, in <module>
    from heatmap.dataGenerator import data_generator_ids
  File "/home/ubuntu/backend/xxswl-backend/heatmap/dataGenerator.py", line 5
    """
    ^
SyntaxError: (unicode error) 'utf-8' codec can't decode byte 0xd2 in position 71: invalid continuation byte
/home/ubuntu/backend/xxswl-backend/heatmap/dataGenerator.py changed, reloading.
Performing system checks...

Watching for file changes with StatReloader
Exception in thread django-main-thread:
Traceback (most recent call last):
  File "/usr/lib/python3.8/threading.py", line 932, in _bootstrap_inner
    self.run()
  File "/usr/lib/python3.8/threading.py", line 870, in run
    self._target(*self._args, **self._kwargs)
  File "/home/ubuntu/.local/lib/python3.8/site-packages/django/utils/autoreload.py", line 53, in wrapper
    fn(*args, **kwargs)
  File "/home/ubuntu/.local/lib/python3.8/site-packages/django/core/management/commands/runserver.py", line 118, in inner_run
    self.check(display_num_errors=True)
  File "/home/ubuntu/.local/lib/python3.8/site-packages/django/core/management/base.py", line 392, in check
    all_issues = checks.run_checks(
  File "/home/ubuntu/.local/lib/python3.8/site-packages/django/core/checks/registry.py", line 70, in run_checks
    new_errors = check(app_configs=app_configs, databases=databases)
  File "/home/ubuntu/.local/lib/python3.8/site-packages/django/core/checks/urls.py", line 13, in check_url_config
    return check_resolver(resolver)
  File "/home/ubuntu/.local/lib/python3.8/site-packages/django/core/checks/urls.py", line 23, in check_resolver
    return check_method()
  File "/home/ubuntu/.local/lib/python3.8/site-packages/django/urls/resolvers.py", line 408, in check
    for pattern in self.url_patterns:
  File "/home/ubuntu/.local/lib/python3.8/site-packages/django/utils/functional.py", line 48, in __get__
    res = instance.__dict__[self.name] = self.func(instance)
  File "/home/ubuntu/.local/lib/python3.8/site-packages/django/urls/resolvers.py", line 589, in url_patterns
    patterns = getattr(self.urlconf_module, "urlpatterns", self.urlconf_module)
  File "/home/ubuntu/.local/lib/python3.8/site-packages/django/utils/functional.py", line 48, in __get__
    res = instance.__dict__[self.name] = self.func(instance)
  File "/home/ubuntu/.local/lib/python3.8/site-packages/django/urls/resolvers.py", line 582, in urlconf_module
    return import_module(self.urlconf_name)
  File "/usr/lib/python3.8/importlib/__init__.py", line 127, in import_module
    return _bootstrap._gcd_import(name[level:], package, level)
  File "<frozen importlib._bootstrap>", line 1014, in _gcd_import
  File "<frozen importlib._bootstrap>", line 991, in _find_and_load
  File "<frozen importlib._bootstrap>", line 975, in _find_and_load_unlocked
  File "<frozen importlib._bootstrap>", line 671, in _load_unlocked
  File "<frozen importlib._bootstrap_external>", line 783, in exec_module
  File "<frozen importlib._bootstrap>", line 219, in _call_with_frames_removed
  File "/home/ubuntu/backend/xxswl-backend/xxswl/urls.py", line 21, in <module>
    path('news/',include('news.urls')),
  File "/home/ubuntu/.local/lib/python3.8/site-packages/django/urls/conf.py", line 34, in include
    urlconf_module = import_module(urlconf_module)
  File "/usr/lib/python3.8/importlib/__init__.py", line 127, in import_module
    return _bootstrap._gcd_import(name[level:], package, level)
  File "<frozen importlib._bootstrap>", line 1014, in _gcd_import
  File "<frozen importlib._bootstrap>", line 991, in _find_and_load
  File "<frozen importlib._bootstrap>", line 975, in _find_and_load_unlocked
  File "<frozen importlib._bootstrap>", line 671, in _load_unlocked
  File "<frozen importlib._bootstrap_external>", line 783, in exec_module
  File "<frozen importlib._bootstrap>", line 219, in _call_with_frames_removed
  File "/home/ubuntu/backend/xxswl-backend/news/urls.py", line 2, in <module>
    from . import views
  File "/home/ubuntu/backend/xxswl-backend/news/views.py", line 10, in <module>
    from heatmap.dataGenerator import data_generator_ids
  File "/home/ubuntu/backend/xxswl-backend/heatmap/dataGenerator.py", line 23
SyntaxError: (unicode error) 'utf-8' codec can't decode byte 0xa3 in position 72: invalid start byte
/home/ubuntu/backend/xxswl-backend/heatmap/dataGenerator.py changed, reloading.
Performing system checks...

Watching for file changes with StatReloader
Exception in thread django-main-thread:
Traceback (most recent call last):
  File "/usr/lib/python3.8/threading.py", line 932, in _bootstrap_inner
    self.run()
  File "/usr/lib/python3.8/threading.py", line 870, in run
    self._target(*self._args, **self._kwargs)
  File "/home/ubuntu/.local/lib/python3.8/site-packages/django/utils/autoreload.py", line 53, in wrapper
    fn(*args, **kwargs)
  File "/home/ubuntu/.local/lib/python3.8/site-packages/django/core/management/commands/runserver.py", line 118, in inner_run
    self.check(display_num_errors=True)
  File "/home/ubuntu/.local/lib/python3.8/site-packages/django/core/management/base.py", line 392, in check
    all_issues = checks.run_checks(
  File "/home/ubuntu/.local/lib/python3.8/site-packages/django/core/checks/registry.py", line 70, in run_checks
    new_errors = check(app_configs=app_configs, databases=databases)
  File "/home/ubuntu/.local/lib/python3.8/site-packages/django/core/checks/urls.py", line 13, in check_url_config
    return check_resolver(resolver)
  File "/home/ubuntu/.local/lib/python3.8/site-packages/django/core/checks/urls.py", line 23, in check_resolver
    return check_method()
  File "/home/ubuntu/.local/lib/python3.8/site-packages/django/urls/resolvers.py", line 408, in check
    for pattern in self.url_patterns:
  File "/home/ubuntu/.local/lib/python3.8/site-packages/django/utils/functional.py", line 48, in __get__
    res = instance.__dict__[self.name] = self.func(instance)
  File "/home/ubuntu/.local/lib/python3.8/site-packages/django/urls/resolvers.py", line 589, in url_patterns
    patterns = getattr(self.urlconf_module, "urlpatterns", self.urlconf_module)
  File "/home/ubuntu/.local/lib/python3.8/site-packages/django/utils/functional.py", line 48, in __get__
    res = instance.__dict__[self.name] = self.func(instance)
  File "/home/ubuntu/.local/lib/python3.8/site-packages/django/urls/resolvers.py", line 582, in urlconf_module
    return import_module(self.urlconf_name)
  File "/usr/lib/python3.8/importlib/__init__.py", line 127, in import_module
    return _bootstrap._gcd_import(name[level:], package, level)
  File "<frozen importlib._bootstrap>", line 1014, in _gcd_import
  File "<frozen importlib._bootstrap>", line 991, in _find_and_load
  File "<frozen importlib._bootstrap>", line 975, in _find_and_load_unlocked
  File "<frozen importlib._bootstrap>", line 671, in _load_unlocked
  File "<frozen importlib._bootstrap_external>", line 783, in exec_module
  File "<frozen importlib._bootstrap>", line 219, in _call_with_frames_removed
  File "/home/ubuntu/backend/xxswl-backend/xxswl/urls.py", line 21, in <module>
    path('news/',include('news.urls')),
  File "/home/ubuntu/.local/lib/python3.8/site-packages/django/urls/conf.py", line 34, in include
    urlconf_module = import_module(urlconf_module)
  File "/usr/lib/python3.8/importlib/__init__.py", line 127, in import_module
    return _bootstrap._gcd_import(name[level:], package, level)
  File "<frozen importlib._bootstrap>", line 1014, in _gcd_import
  File "<frozen importlib._bootstrap>", line 991, in _find_and_load
  File "<frozen importlib._bootstrap>", line 975, in _find_and_load_unlocked
  File "<frozen importlib._bootstrap>", line 671, in _load_unlocked
  File "<frozen importlib._bootstrap_external>", line 783, in exec_module
  File "<frozen importlib._bootstrap>", line 219, in _call_with_frames_removed
  File "/home/ubuntu/backend/xxswl-backend/news/urls.py", line 2, in <module>
    from . import views
  File "/home/ubuntu/backend/xxswl-backend/news/views.py", line 10, in <module>
    from heatmap.dataGenerator import data_generator_ids
  File "/home/ubuntu/backend/xxswl-backend/heatmap/dataGenerator.py", line 29
SyntaxError: (unicode error) 'utf-8' codec can't decode byte 0xb5 in position 0: invalid start byte
/home/ubuntu/backend/xxswl-backend/heatmap/dataGenerator.py changed, reloading.
Performing system checks...

Watching for file changes with StatReloader
/home/ubuntu/backend/xxswl-backend/heatmap/dataGenerator.py changed, reloading.
Performing system checks...

System check identified no issues (0 silenced).
November 04, 2020 - 18:02:13
Django version 3.1.1, using settings 'xxswl.settings'
Starting development server at http://0.0.0.0:30000/
Quit the server with CONTROL-C.
Watching for file changes with StatReloader
/home/ubuntu/backend/xxswl-backend/heatmap/views.py changed, reloading.
Performing system checks...

System check identified no issues (0 silenced).
November 04, 2020 - 18:15:37
Django version 3.1.1, using settings 'xxswl.settings'
Starting development server at http://0.0.0.0:30000/
Quit the server with CONTROL-C.
Watching for file changes with StatReloader
